Workbook

Sheet SyS
A1: Cuenta - Denominación | B1: Clave (CC_Cuenta) | K1: 0 | M1: 0 | P1: 0
A2: 1 - Oficina General
A3: 421030000 - IVA crédito fiscal no computable | B3: 1_421030000 | K3: 1238.25 | M3: 0 | P3: 1238.25
A4: 421050000 - Sueldos Adm. | B4: 1_421050000 | K4: 8810.54 | M4: 0 | P4: 8810.54
A5: 421060000 - Cargas sociales Adm. | B5: 1_421060000 | K5: 2558.21 | M5: 0 | P5: 2558.21
A6: 424500000 - Cargas sociales Campo | B6: 1_424500000 | K6: 0 | M6: 0 | P6: 0
A7: 425110000 - Refrigerios Adm Gral. | B7: 1_425110000 | K7: 0 | M7: 0 | P7: 0
A8: 425170000 - Mensajeria Adm. Gral. | B8: 1_425170000 | K8: 0 | M8: 0 | P8: 0
A9: 425190000 - Honorarios Profesionales Adm. Gral. | B9: 1_425190000 | K9: 6000 | M9: 0 | P9: 6000
A10: 425220000 - Gastos y Comisiones Bancarias Adm. Gral | B10: 1_425220000 | K10: 176.08 | M10: 0 | P10: 176.08
A11: 425230000 - Imp. a los Débitos y Créditos Bancarios Ad. Gral. | B11: 1_425230000 | K11: 427.8 | M11: 0 | P11: 427.8
A12: 425250000 - Amortizaciones Adm. Gral. | B12: 1_425250000 | K12: 3918.01 | M12: 0 | P12: 3918.01
A13: 425300000 - Gst Varios Oficina Adm. Gral. | B13: 1_425300000 | K13: 0 | M13: 0 | P13: 0
A14: 425310000 - Vacaciones Adm Gral. | B14: 1_425310000 | K14: 395.49 | M14: 0 | P14: 395.49
... A19: 433030000 - Honorarios Profesionales Adm. Gral. USD | B19: 1_433030000 | K19: 0 | M19: 0 | P19: 0
A21: 2 - Exploración Regional
A22: 421070000 - Movilidad y viáticos Adm. | B22: 2_421070000 | K22: 0 | M22: 0 | P22: 0
A23: 424220000 - Comida | B23: 2_424220000 | K23: 0 | M23: 0 | P23: 0
A24: 425110000 - Refrigerios Adm Gral. | B24: 2_425110000 | K24: 634.65 | M24: 0 | P24: 634.65
A25: 425120000 - Movilidad y Viáticos Adm. Gral. | B25: 2_425120000 | K25: 123.47 | M25: 0 | P25: 123.47
A26: 425150000 - Alquiler Inmueble Adm. Gral. | B26: 2_425150000 | K26: 1181.74 | M26: 0 | P26: 1181.74
A27: 425180000 - Comunicaciones Adm. Gral | B27: 2_425180000 | K27: 0 | M27: 0 | P27: 0
A28: 425200000 - Combustible Adm Gral. | B28: 2_425200000 | K28: 142.21 | M28: 0 | P28: 142.21
A29: 425300000 - Gst Varios Oficina Adm. Gral. | B29: 2_425300000 | K29: 130.94 | M29: 0 | P29: 130.94
A30: 425400000 - Servicios Informáticos Adm. Gral. | B30: 2_425400000 | K30: 0 | M30: 0 | P30: 0
A31: 425500000 - Servicios Públicos Adm. Gral. | B31: 2_425500000 | K31: 0 | M31: 0 | P31: 0
A32: 425600000 - Gst Mantenimiento Adm. Gral. | B32: 2_425600000 | K32: 0 | M32: 0 | P32: 0
A33: 425700000 - Alojamiento Adm. Gral. | B33: 2_425700000 | K33: 64.7 | M33: 0 | P33: 64.7
... A66: 426960000 - Análisis de Muestras Gs de Campo | B66: 2_426960000 | K66: 818.52 | M66: 0 | P66: 818.52
A68: 13 - Cerro Abanico
A69: 426150000 - Servicios Públicos Gs Campo | B69: 13_426150000 | K69: 0 | M69: 0 | P69: 0
A71: 14 - Cerro La Mina
A72: 426150000 - Servicios Públicos Gs Campo | B72: 14_426150000 | K72: 0 | M72: 0 | P72: 0
A73: 426800000 - Análisis Geoquimicos - Gtos Laboratorio Gs Campo | B73: 14_426800000 | K73: 0 | M73: 0 | P73: 0
A75: 15 - Cañadon del Moro
A76: 424400000 - Sueldos Campo | B76: 15_424400000 | K76: 10334.79 | M76: 0 | P76: 10334.79
A77: 424500000 - Cargas sociales Campo | B77: 15_424500000 | K77: 2716.28 | M77: 0 | P77: 2716.28
A78: 425150000 - Alquiler Inmueble Adm. Gral. | B78: 15_425150000 | K78: 1235.4 | M78: 0 | P78: 1235.4
A79: 426220000 - Alquiler Inmueble Gst Campo | B79: 15_426220000 | K79: 0 | M79: 0 | P79: 0
A81: 16 - Los Menucos
...

Sheet Sumas y Saldos
A1: SOUTHERN COPPER ARGENTINA S.R.L.
A2: 46113
A3: En Dólares
C4: OFICINA GENERAL | F4: EXPLORACIÓN REGIONAL | I4: TANQUE NEGRO | L4: SAMENTA | O4: CERRO LA MINA | R4: CAÑADON DEL MORO | V4: LOS MENUCOS | X4: CERRO ABANICO | AA4: CENTRO ESPERANZA | AD4: PROYECTO LOS MORTERITOS | AG4: LONCO VACA - PELENQUE | AJ4: PROYECTO SOL | AM4: GASTOS GENERALES | AP4: TRES CONOS | AS4: LA CHILENA | AV4: SOL | AY4: LOS MORTERITOS | BB4: LAS SANTAS | BE4: SHEYLA | BH4: SHEYLA I | BK4: LA HOYADA | BN4: REGIONAL CATAMARCA | BQ4: TOTALES
C5: DEBE | D5: HABER | E5: SALDO | F5: DEBE | G5: HABER | H5: SALDO | I5: DEBE | J5: HABER | K5: SALDO | L5: DEBE | M5: HABER | N5: SALDO | O5: DEBE | P5: HABER | Q5: SALDO | R5: DEBE | S5: HABER | T5: SALDO | U5: DEBE | V5: HABER | W5: SALDO | X5: DEBE | Y5: HABER | Z5: SALDO | AA5: DEBE | AB5: HABER | AC5: SALDO | AD5: DEBE | AE5: HABER | AF5: SALDO | AG5: DEBE | AH5: HABER | AI5: SALDO | AJ5: DEBE | AK5: HABER | AL5: SALDO | AM5: DEBE | AN5: HABER | AO5: SALDO | AP5: DEBE | AQ5: HABER | AR5: SALDO | AS5: DEBE | AT5: HABER | AU5: SALDO | AV5: DEBE | AW5: HABER | AX5: SALDO | AY5: DEBE | AZ5: HABER | BA5: SALDO | BB5: DEBE | BC5: HABER | BD5: SALDO | BE5: DEBE | BF5: HABER | BG5: SALDO | BH5: DEBE | BI5: HABER | BJ5: SALDO | BK5: DEBE | BL5: HABER | BM5: SALDO | BN5: DEBE | BO5: HABER | BP5: SALDO | BQ5: SALDOS
K6: 0
A7: 40000000 | B7: RESULTADOS | C7: =IFERROR(VLOOKUP("1_"&A7,SyS!$B:$P,10,FALSE()),0) -> 0 | D7: =IFERROR(VLOOKUP("1_"&A7,SyS!$B:$P,12,FALSE()),0) -> 0 | E7: =+C7-D7 -> 0 | F7: =IFERROR(VLOOKUP("2_"&A7,SyS!$B:$P,10,FALSE()),0) -> 0 | G7: =IFERROR(VLOOKUP("2_"&A7,SyS!$B:$P,12,FALSE()),0) -> 0 | H7: =+F7-G7 -> 0 | O7: =IFERROR(VLOOKUP("14_"&A7,SyS!$B:$P,10,FALSE()),0) -> 0 | P7: =IFERROR(VLOOKUP("14_"&A7,SyS!$B:$P,12,FALSE()),0) -> 0 | Q7: =+O7-P7 -> 0 | R7: =IFERROR(VLOOKUP("15_"&A7,SyS!$B:$P,10,FALSE()),0) -> 0 | S7: =IFERROR(VLOOKUP("15_"&A7,SyS!$B:$P,12,FALSE()),0) -> 0 | T7: =+R7-S7 -> 0 | U7: =IFERROR(VLOOKUP("16_"&A7,SyS!$B:$P,10,FALSE()),0) -> 0 | V7: =IFERROR(VLOOKUP("16_"&A7,SyS!$B:$P,12,FALSE()),0) -> 0 | W7: =+U7-V7 -> 0 | X7: =IFERROR(VLOOKUP("13_"&A7,SyS!$B:$P,10,FALSE()),0) -> 0 | Y7: =IFERROR(VLOOKUP("13_"&A7,SyS!$B:$P,12,FALSE()),0) -> 0 | Z7: =+X7-Y7 -> 0 | AA7: =IFERROR(VLOOKUP("17_"&A7,SyS!$B:$P,10,FALSE()),0) -> 0 | AB7: =IFERROR(VLOOKUP("17_"&A7,SyS!$B:$P,12,FALSE()),0) -> 0 | AC7: =+AA7-AB7 -> 0 | AG7: =IFERROR(VLOOKUP("19_"&A7,SyS!$B:$P,10,FALSE()),0) -> 0 | AH7: =IFERROR(VLOOKUP("19_"&A7,SyS!$B:$P,12,FALSE()),0) -> 0 | AI7: =+AG7-AH7 -> 0 | AM7: =IFERROR(VLOOKUP("23_"&A7,SyS!$B:$P,10,FALSE()),0) -> 0 | AN7: =IFERROR(VLOOKUP("23_"&A7,SyS!$B:$P,12,FALSE()),0) -> 0 | AO7: =+AM7-AN7 -> 0 | BK7: =IFERROR(VLOOKUP("29_"&A7,SyS!$B:$P,10,FALSE()),0) -> 0 | BL7: =IFERROR(VLOOKUP("29_"&A7,SyS!$B:$P,12,FALSE()),0) -> 0 | BM7: =+BK7-BL7 -> 0 | BN7: =IFERROR(VLOOKUP("30_"&A7,SyS!$B:$P,10,FALSE()),0) -> 0 | BO7: =IFERROR(VLOOKUP("30_"&A7,SyS!$B:$P,12,FALSE()),0) -> 0 | BP7: =+BN7-BO7 -> 0 | BQ7: =+E7+H7+K7+Q7+T7+W7+Z7+AC7+AF7+AI7+AL7+AO7+AR7+AU7+AX7+BA7+BD7+BG7+BJ7+BM7+BP7 -> 0
A8: 41000000 | B8: INGRESOS | C8: =IFERROR(VLOOKUP("1_"&A8,SyS!$B:$P,10,FALSE()),0) -> 0 | D8: =IFERROR(VLOOKUP("1_"&A8,SyS!$B:$P,12,FALSE()),0) -> 0 | E8: =+C8-D8 -> 0 | F8: =IFERROR(VLOOKUP("2_"&A8,SyS!$B:$P,10,FALSE()),0) -> 0 | G8: =IFERROR(VLOOKUP("2_"&A8,SyS!$B:$P,12,FALSE()),0) -> 0 | H8: =+F8-G8 -> 0 | O8: =IFERROR(VLOOKUP("14_"&A8,SyS!$B:$P,10,FALSE()),0) -> 0 | P8: =IFERROR(VLOOKUP("14_"&A8,SyS!$B:$P,12,FALSE()),0) -> 0 | Q8: =+O8-P8 -> 0 | R8: =IFERROR(VLOOKUP("15_"&A8,SyS!$B:$P,10,FALSE()),0) -> 0 | S8: =IFERROR(VLOOKUP("15_"&A8,SyS!$B:$P,12,FALSE()),0) -> 0 | T8: =+R8-S8 -> 0 | U8: =IFERROR(VLOOKUP("16_"&A8,SyS!$B:$P,10,FALSE()),0) -> 0 | V8: =IFERROR(VLOOKUP("16_"&A8,SyS!$B:$P,12,FALSE()),0) -> 0 | W8: =+U8-V8 -> 0 | X8: =IFERROR(VLOOKUP("13_"&A8,SyS!$B:$P,10,FALSE()),0) -> 0 | Y8: =IFERROR(VLOOKUP("13_"&A8,SyS!$B:$P,12,FALSE()),0) -> 0 | Z8: =+X8-Y8 -> 0 | AA8: =IFERROR(VLOOKUP("17_"&A8,SyS!$B:$P,10,FALSE()),0) -> 0 | AB8: =IFERROR(VLOOKUP("17_"&A8,SyS!$B:$P,12,FALSE()),0) -> 0 | AC8: =+AA8-AB8 -> 0 | AG8: =IFERROR(VLOOKUP("19_"&A8,SyS!$B:$P,10,FALSE()),0) -> 0 | AH8: =IFERROR(VLOOKUP("19_"&A8,SyS!$B:$P,12,FALSE()),0) -> 0 | AI8: =+AG8-AH8 -> 0 | AM8: =IFERROR(VLOOKUP("23_"&A8,SyS!$B:$P,10,FALSE()),0) -> 0 | AN8: =IFERROR(VLOOKUP("23_"&A8,SyS!$B:$P,12,FALSE()),0) -> 0 | AO8: =+AM8-AN8 -> 0 | BK8: =IFERROR(VLOOKUP("29_"&A8,SyS!$B:$P,10,FALSE()),0) -> 0 | BL8: =IFERROR(VLOOKUP("29_"&A8,SyS!$B:$P,12,FALSE()),0) -> 0 | BM8: =+BK8-BL8 -> 0 | BN8: =IFERROR(VLOOKUP("30_"&A8,SyS!$B:$P,10,FALSE()),0) -> 0 | BO8: =IFERROR(VLOOKUP("30_"&A8,SyS!$B:$P,12,FALSE()),0) -> 0 | BP8: =+BN8-BO8 -> 0 | BQ8: =+E8+H8+K8+Q8+T8+W8+Z8+AC8+AF8+AI8+AL8+AO8+AR8+AU8+AX8+BA8+BD8+BG8+BJ8+BM8+BP8 -> 0
A9: 41100000 | B9: VENTAS | C9: =IFERROR(VLOOKUP("1_"&A9,SyS!$B:$P,10,FALSE()),0) -> 0 | D9: =IFERROR(VLOOKUP("1_"&A9,SyS!$B:$P,12,FALSE()),0) -> 0 | E9: =+C9-D9 -> 0 | F9: =IFERROR(VLOOKUP("2_"&A9,SyS!$B:$P,10,FALSE()),0) -> 0 | G9: =IFERROR(VLOOKUP("2_"&A9,SyS!$B:$P,12,FALSE()),0) -> 0 | H9: =+F9-G9 -> 0 | O9: =IFERROR(VLOOKUP("14_"&A9,SyS!$B:$P,10,FALSE()),0) -> 0 | P9: =IFERROR(VLOOKUP("14_"&A9,SyS!$B:$P,12,FALSE()),0) -> 0 | Q9: =+O9-P9 -> 0 | R9: =IFERROR(VLOOKUP("15_"&A9,SyS!$B:$P,10,FALSE()),0) -> 0 | S9: =IFERROR(VLOOKUP("15_"&A9,SyS!$B:$P,12,FALSE()),0) -> 0 | T9: =+R9-S9 -> 0 | U9: =IFERROR(VLOOKUP("16_"&A9,SyS!$B:$P,10,FALSE()),0) -> 0 | V9: =IFERROR(VLOOKUP("16_"&A9,SyS!$B:$P,12,FALSE()),0) -> 0 | W9: =+U9-V9 -> 0 | X9: =IFERROR(VLOOKUP("13_"&A9,SyS!$B:$P,10,FALSE()),0) -> 0 | Y9: =IFERROR(VLOOKUP("13_"&A9,SyS!$B:$P,12,FALSE()),0) -> 0 | Z9: =+X9-Y9 -> 0 | AA9: =IFERROR(VLOOKUP("17_"&A9,SyS!$B:$P,10,FALSE()),0) -> 0 | AB9: =IFERROR(VLOOKUP("17_"&A9,SyS!$B:$P,12,FALSE()),0) -> 0 | AC9: =+AA9-AB9 -> 0 | AG9: =IFERROR(VLOOKUP("19_"&A9,SyS!$B:$P,10,FALSE()),0) -> 0 | AH9: =IFERROR(VLOOKUP("19_"&A9,SyS!$B:$P,12,FALSE()),0) -> 0 | AI9: =+AG9-AH9 -> 0 | AM9: =IFERROR(VLOOKUP("23_"&A9,SyS!$B:$P,10,FALSE()),0) -> 0 | AN9: =IFERROR(VLOOKUP("23_"&A9,SyS!$B:$P,12,FALSE()),0) -> 0 | AO9: =+AM9-AN9 -> 0 | BK9: =IFERROR(VLOOKUP("29_"&A9,SyS!$B:$P,10,FALSE()),0) -> 0 | BL9: =IFERROR(VLOOKUP("29_"&A9,SyS!$B:$P,12,FALSE()),0) -> 0 | BM9: =+BK9-BL9 -> 0 | BN9: =IFERROR(VLOOKUP("30_"&A9,SyS!$B:$P,10,FALSE()),0) -> 0 | BO9: =IFERROR(VLOOKUP("30_"&A9,SyS!$B:$P,12,FALSE()),0) -> 0 | BP9: =+BN9-BO9 -> 0 | BQ9: =+E9+H9+K9+Q9+T9+W9+Z9+AC9+AF9+AI9+AL9+AO9+AR9+AU9+AX9+BA9+BD9+BG9+BJ9+BM9+BP9 -> 0
A10: 41200000 | B10: OTROS INGRESOS | C10: =IFERROR(VLOOKUP("1_"&A10,SyS!$B:$P,10,FALSE()),0) -> 0 | D10: =IFERROR(VLOOKUP("1_"&A10,SyS!$B:$P,12,FALSE()),0) -> 0 | E10: =+C10-D10 -> 0 | F10: =IFERROR(VLOOKUP("2_"&A10,SyS!$B:$P,10,FALSE()),0) -> 0 | G10: =IFERROR(VLOOKUP("2_"&A10,SyS!$B:$P,12,FALSE()),0) -> 0 | H10: =+F10-G10 -> 0 | O10: =IFERROR(VLOOKUP("14_"&A10,SyS!$B:$P,10,FALSE()),0) -> 0 | P10: =IFERROR(VLOOKUP("14_"&A10,SyS!$B:$P,12,FALSE()),0) -> 0 | Q10: =+O10-P10 -> 0 | R10: =IFERROR(VLOOKUP("15_"&A10,SyS!$B:$P,10,FALSE()),0) -> 0 | S10: =IFERROR(VLOOKUP("15_"&A10,SyS!$B:$P,12,FALSE()),0) -> 0 | T10: =+R10-S10 -> 0 | U10: =IFERROR(VLOOKUP("16_"&A10,SyS!$B:$P,10,FALSE()),0) -> 0 | V10: =IFERROR(VLOOKUP("16_"&A10,SyS!$B:$P,12,FALSE()),0) -> 0 | W10: =+U10-V10 -> 0 | X10: =IFERROR(VLOOKUP("13_"&A10,SyS!$B:$P,10,FALSE()),0) -> 0 | Y10: =IFERROR(VLOOKUP("13_"&A10,SyS!$B:$P,12,FALSE()),0) -> 0 | Z10: =+X10-Y10 -> 0 | AA10: =IFERROR(VLOOKUP("17_"&A10,SyS!$B:$P,10,FALSE()),0) -> 0 | AB10: =IFERROR(VLOOKUP("17_"&A10,SyS!$B:$P,12,FALSE()),0) -> 0 | AC10: =+AA10-AB10 -> 0 | AG10: =IFERROR(VLOOKUP("19_"&A10,SyS!$B:$P,10,FALSE()),0) -> 0 | AH10: =IFERROR(VLOOKUP("19_"&A10,SyS!$B:$P,12,FALSE()),0) -> 0 | AI10: =+AG10-AH10 -> 0 | AM10: =IFERROR(VLOOKUP("23_"&A10,SyS!$B:$P,10,FALSE()),0) -> 0 | AN10: =IFERROR(VLOOKUP("23_"&A10,SyS!$B:$P,12,FALSE()),0) -> 0 | AO10: =+AM10-AN10 -> 0 | BK10: =IFERROR(VLOOKUP("29_"&A10,SyS!$B:$P,10,FALSE()),0) -> 0 | BL10: =IFERROR(VLOOKUP("29_"&A10,SyS!$B:$P,12,FALSE()),0) -> 0 | BM10: =+BK10-BL10 -> 0 | BN10: =IFERROR(VLOOKUP("30_"&A10,SyS!$B:$P,10,FALSE()),0) -> 0 | BO10: =IFERROR(VLOOKUP("30_"&A10,SyS!$B:$P,12,FALSE()),0) -> 0 | BP10: =+BN10-BO10 -> 0 | BQ10: =+E10+H10+K10+Q10+T10+W10+Z10+AC10+AF10+AI10+AL10+AO10+AR10+AU10+AX10+BA10+BD10+BG10+BJ10+BM10+BP10 -> 0
A11: 41230000 | B11: Envío muestras Chile | C11: =IFERROR(VLOOKUP("1_"&A11,SyS!$B:$P,10,FALSE()),0) -> 0 | D11: =IFERROR(VLOOKUP("1_"&A11,SyS!$B:$P,12,FALSE()),0) -> 0 | E11: =+C11-D11 -> 0 | F11: =IFERROR(VLOOKUP("2_"&A11,SyS!$B:$P,10,FALSE()),0) -> 0 | G11: =IFERROR(VLOOKUP("2_"&A11,SyS!$B:$P,12,FALSE()),0) -> 0 | H11: =+F11-G11 -> 0 | O11: =IFERROR(VLOOKUP("14_"&A11,SyS!$B:$P,10,FALSE()),0) -> 0 | P11: =IFERROR(VLOOKUP("14_"&A11,SyS!$B:$P,12,FALSE()),0) -> 0 | Q11: =+O11-P11 -> 0 | R11: =IFERROR(VLOOKUP("15_"&A11,SyS!$B:$P,10,FALSE()),0) -> 0 | S11: =IFERROR(VLOOKUP("15_"&A11,SyS!$B:$P,12,FALSE()),0) -> 0 | T11: =+R11-S11 -> 0 | U11: =IFERROR(VLOOKUP("16_"&A11,SyS!$B:$P,10,FALSE()),0) -> 0 | V11: =IFERROR(VLOOKUP("16_"&A11,SyS!$B:$P,12,FALSE()),0) -> 0 | W11: =+U11-V11 -> 0 | X11: =IFERROR(VLOOKUP("13_"&A11,SyS!$B:$P,10,FALSE()),0) -> 0 | Y11: =IFERROR(VLOOKUP("13_"&A11,SyS!$B:$P,12,FALSE()),0) -> 0 | Z11: =+X11-Y11 -> 0 | AA11: =IFERROR(VLOOKUP("17_"&A11,SyS!$B:$P,10,FALSE()),0) -> 0 | AB11: =IFERROR(VLOOKUP("17_"&A11,SyS!$B:$P,12,FALSE()),0) -> 0 | AC11: =+AA11-AB11 -> 0 | AG11: =IFERROR(VLOOKUP("19_"&A11,SyS!$B:$P,10,FALSE()),0) -> 0 | AH11: =IFERROR(VLOOKUP("19_"&A11,SyS!$B:$P,12,FALSE()),0) -> 0 | AI11: =+AG11-AH11 -> 0 | AM11: =IFERROR(VLOOKUP("23_"&A11,SyS!$B:$P,10,FALSE()),0) -> 0 | AN11: =IFERROR(VLOOKUP("23_"&A11,SyS!$B:$P,12,FALSE()),0) -> 0 | AO11: =+AM11-AN11 -> 0 | BK11: =IFERROR(VLOOKUP("29_"&A11,SyS!$B:$P,10,FALSE()),0) -> 0 | BL11: =IFERROR(VLOOKUP("29_"&A11,SyS!$B:$P,12,FALSE()),0) -> 0 | BM11: =+BK11-BL11 -> 0 | BN11: =IFERROR(VLOOKUP("30_"&A11,SyS!$B:$P,10,FALSE()),0) -> 0 | BO11: =IFERROR(VLOOKUP("30_"&A11,SyS!$B:$P,12,FALSE()),0) -> 0 | BP11: =+BN11-BO11 -> 0 | BQ11: =+E11+H11+K11+Q11+T11+W11+Z11+AC11+AF11+AI11+AL11+AO11+AR11+AU11+AX11+BA11+BD11+BG11+BJ11+BM11+BP11 -> 0
A12: 41210000 | B12: Baja bien de uso | C12: =IFERROR(VLOOKUP("1_"&A12,SyS!$B:$P,10,FALSE()),0) -> 0 | D12: =IFERROR(VLOOKUP("1_"&A12,SyS!$B:$P,12,FALSE()),0) -> 0 | E12: =+C12-D12 -> 0 | F12: =IFERROR(VLOOKUP("2_"&A12,SyS!$B:$P,10,FALSE()),0) -> 0 | G12: =IFERROR(VLOOKUP("2_"&A12,SyS!$B:$P,12,FALSE()),0) -> 0 | H12: =+F12-G12 -> 0 | O12: =IFERROR(VLOOKUP("14_"&A12,SyS!$B:$P,10,FALSE()),0) -> 0 | P12: =IFERROR(VLOOKUP("14_"&A12,SyS!$B:$P,12,FALSE()),0) -> 0 | Q12: =+O12-P12 -> 0 | R12: =IFERROR(VLOOKUP("15_"&A12,SyS!$B:$P,10,FALSE()),0) -> 0 | S12: =IFERROR(VLOOKUP("15_"&A12,SyS!$B:$P,12,FALSE()),0) -> 0 | T12: =+R12-S12 -> 0 | U12: =IFERROR(VLOOKUP("16_"&A12,SyS!$B:$P,10,FALSE()),0) -> 0 | V12: =IFERROR(VLOOKUP("16_"&A12,SyS!$B:$P,12,FALSE()),0) -> 0 | W12: =+U12-V12 -> 0 | X12: =IFERROR(VLOOKUP("13_"&A12,SyS!$B:$P,10,FALSE()),0) -> 0 | Y12: =IFERROR(VLOOKUP("13_"&A12,SyS!$B:$P,12,FALSE()),0) -> 0 | Z12: =+X12-Y12 -> 0 | AA12: =IFERROR(VLOOKUP("17_"&A12,SyS!$B:$P,10,FALSE()),0) -> 0 | AB12: =IFERROR(VLOOKUP("17_"&A12,SyS!$B:$P,12,FALSE()),0) -> 0 | AC12: =+AA12-AB12 -> 0 | AG12: =IFERROR(VLOOKUP("19_"&A12,SyS!$B:$P,10,FALSE()),0) -> 0 | AH12: =IFERROR(VLOOKUP("19_"&A12,SyS!$B:$P,12,FALSE()),0) -> 0 | AI12: =+AG12-AH12 -> 0 | AM12: =IFERROR(VLOOKUP("23_"&A12,SyS!$B:$P,10,FALSE()),0) -> 0 | AN12: =IFERROR(VLOOKUP("23_"&A12,SyS!$B:$P,12,FALSE()),0) -> 0 | AO12: =+AM12-AN12 -> 0 | BK12: =IFERROR(VLOOKUP("29_"&A12,SyS!$B:$P,10,FALSE()),0) -> 0 | BL12: =IFERROR(VLOOKUP("29_"&A12,SyS!$B:$P,12,FALSE()),0) -> 0 | BM12: =+BK12-BL12 -> 0 | BN12: =IFERROR(VLOOKUP("30_"&A12,SyS!$B:$P,10,FALSE()),0) -> 0 | BO12: =IFERROR(VLOOKUP("30_"&A12,SyS!$B:$P,12,FALSE()),0) -> 0 | BP12: =+BN12-BO12 -> 0 | BQ12: =+E12+H12+K12+Q12+T12+W12+Z12+AC12+AF12+AI12+AL12+AO12+AR12+AU12+AX12+BA12+BD12+BG12+BJ12+BM12+BP12 -> 0
A13: 42000000 | B13: EGRESOS | C13: =IFERROR(VLOOKUP("1_"&A13,SyS!$B:$P,10,FALSE()),0) -> 0 | D13: =IFERROR(VLOOKUP("1_"&A13,SyS!$B:$P,12,FALSE()),0) -> 0 | E13: =+C13-D13 -> 0 | F13: =IFERROR(VLOOKUP("2_"&A13,SyS!$B:$P,10,FALSE()),0) -> 0 | G13: =IFERROR(VLOOKUP("2_"&A13,SyS!$B:$P,12,FALSE()),0) -> 0 | H13: =+F13-G13 -> 0 | O13: =IFERROR(VLOOKUP("14_"&A13,SyS!$B:$P,10,FALSE()),0) -> 0 | P13: =IFERROR(VLOOKUP("14_"&A13,SyS!$B:$P,12,FALSE()),0) -> 0 | Q13: =+O13-P13 -> 0 | R13: =IFERROR(VLOOKUP("15_"&A13,SyS!$B:$P,10,FALSE()),0) -> 0 | S13: =IFERROR(VLOOKUP("15_"&A13,SyS!$B:$P,12,FALSE()),0) -> 0 | T13: =+R13-S13 -> 0 | U13: =IFERROR(VLOOKUP("16_"&A13,SyS!$B:$P,10,FALSE()),0) -> 0 | V13: =IFERROR(VLOOKUP("16_"&A13,SyS!$B:$P,12,FALSE()),0) -> 0 | W13: =+U13-V13 -> 0 | X13: =IFERROR(VLOOKUP("13_"&A13,SyS!$B:$P,10,FALSE()),0) -> 0 | Y13: =IFERROR(VLOOKUP("13_"&A13,SyS!$B:$P,12,FALSE()),0) -> 0 | Z13: =+X13-Y13 -> 0 | AA13: =IFERROR(VLOOKUP("17_"&A13,SyS!$B:$P,10,FALSE()),0) -> 0 | AB13: =IFERROR(VLOOKUP("17_"&A13,SyS!$B:$P,12,FALSE()),0) -> 0 | AC13: =+AA13-AB13 -> 0 | AG13: =IFERROR(VLOOKUP("19_"&A13,SyS!$B:$P,10,FALSE()),0) -> 0 | AH13: =IFERROR(VLOOKUP("19_"&A13,SyS!$B:$P,12,FALSE()),0) -> 0 | AI13: =+AG13-AH13 -> 0 | AM13: =IFERROR(VLOOKUP("23_"&A13,SyS!$B:$P,10,FALSE()),0) -> 0 | AN13: =IFERROR(VLOOKUP("23_"&A13,SyS!$B:$P,12,FALSE()),0) -> 0 | AO13: =+AM13-AN13 -> 0 | BK13: =IFERROR(VLOOKUP("29_"&A13,SyS!$B:$P,10,FALSE()),0) -> 0 | BL13: =IFERROR(VLOOKUP("29_"&A13,SyS!$B:$P,12,FALSE()),0) -> 0 | BM13: =+BK13-BL13 -> 0 | BN13: =IFERROR(VLOOKUP("30_"&A13,SyS!$B:$P,10,FALSE()),0) -> 0 | BO13: =IFERROR(VLOOKUP("30_"&A13,SyS!$B:$P,12,FALSE()),0) -> 0 | BP13: =+BN13-BO13 -> 0 | BQ13: =+E13+H13+K13+Q13+T13+W13+Z13+AC13+AF13+AI13+AL13+AO13+AR13+AU13+AX13+BA13+BD13+BG13+BJ13+BM13+BP13 -> 0
A14: 42100000 | B14: GASTOS DE COMERCIALIZACION | C14: =IFERROR(VLOOKUP("1_"&A14,SyS!$B:$P,10,FALSE()),0) -> 0 | D14: =IFERROR(VLOOKUP("1_"&A14,SyS!$B:$P,12,FALSE()),0) -> 0 | E14: =+C14-D14 -> 0 | F14: =IFERROR(VLOOKUP("2_"&A14,SyS!$B:$P,10,FALSE()),0) -> 0 | G14: =IFERROR(VLOOKUP("2_"&A14,SyS!$B:$P,12,FALSE()),0) -> 0 | H14: =+F14-G14 -> 0 | O14: =IFERROR(VLOOKUP("14_"&A14,SyS!$B:$P,10,FALSE()),0) -> 0 | P14: =IFERROR(VLOOKUP("14_"&A14,SyS!$B:$P,12,FALSE()),0) -> 0 | Q14: =+O14-P14 -> 0 | R14: =IFERROR(VLOOKUP("15_"&A14,SyS!$B:$P,10,FALSE()),0) -> 0 | S14: =IFERROR(VLOOKUP("15_"&A14,SyS!$B:$P,12,FALSE()),0) -> 0 | T14: =+R14-S14 -> 0 | U14: =IFERROR(VLOOKUP("16_"&A14,SyS!$B:$P,10,FALSE()),0) -> 0 | V14: =IFERROR(VLOOKUP("16_"&A14,SyS!$B:$P,12,FALSE()),0) -> 0 | W14: =+U14-V14 -> 0 | X14: =IFERROR(VLOOKUP("13_"&A14,SyS!$B:$P,10,FALSE()),0) -> 0 | Y14: =IFERROR(VLOOKUP("13_"&A14,SyS!$B:$P,12,FALSE()),0) -> 0 | Z14: =+X14-Y14 -> 0 | AA14: =IFERROR(VLOOKUP("17_"&A14,SyS!$B:$P,10,FALSE()),0) -> 0 | AB14: =IFERROR(VLOOKUP("17_"&A14,SyS!$B:$P,12,FALSE()),0) -> 0 | AC14: =+AA14-AB14 -> 0 | AG14: =IFERROR(VLOOKUP("19_"&A14,SyS!$B:$P,10,FALSE()),0) -> 0 | AH14: =IFERROR(VLOOKUP("19_"&A14,SyS!$B:$P,12,FALSE()),0) -> 0 | AI14: =+AG14-AH14 -> 0 | AM14: =IFERROR(VLOOKUP("23_"&A14,SyS!$B:$P,10,FALSE()),0) -> 0 | AN14: =IFERROR(VLOOKUP("23_"&A14,SyS!$B:$P,12,FALSE()),0) -> 0 | AO14: =+AM14-AN14 -> 0 | BK14: =IFERROR(VLOOKUP("29_"&A14,SyS!$B:$P,10,FALSE()),0) -> 0 | BL14: =IFERROR(VLOOKUP("29_"&A14,SyS!$B:$P,12,FALSE()),0) -> 0 | BM14: =+BK14-BL14 -> 0 | BN14: =IFERROR(VLOOKUP("30_"&A14,SyS!$B:$P,10,FALSE()),0) -> 0 | BO14: =IFERROR(VLOOKUP("30_"&A14,SyS!$B:$P,12,FALSE()),0) -> 0 | BP14: =+BN14-BO14 -> 0 | BQ14: =+E14+H14+K14+Q14+T14+W14+Z14+AC14+AF14+AI14+AL14+AO14+AR14+AU14+AX14+BA14+BD14+BG14+BJ14+BM14+BP14 -> 0
A15: 42101000 | B15: Honorarios legales | C15: =IFERROR(VLOOKUP("1_"&A15,SyS!$B:$P,10,FALSE()),0) -> 0 | D15: =IFERROR(VLOOKUP("1_"&A15,SyS!$B:$P,12,FALSE()),0) -> 0 | E15: =+C15-D15 -> 0 | F15: =IFERROR(VLOOKUP("2_"&A15,SyS!$B:$P,10,FALSE()),0) -> 0 | G15: =IFERROR(VLOOKUP("2_"&A15,SyS!$B:$P,12,FALSE()),0) -> 0 | H15: =+F15-G15 -> 0 | O15: =IFERROR(VLOOKUP("14_"&A15,SyS!$B:$P,10,FALSE()),0) -> 0 | P15: =IFERROR(VLOOKUP("14_"&A15,SyS!$B:$P,12,FALSE()),0) -> 0 | Q15: =+O15-P15 -> 0 | R15: =IFERROR(VLOOKUP("15_"&A15,SyS!$B:$P,10,FALSE()),0) -> 0 | S15: =IFERROR(VLOOKUP("15_"&A15,SyS!$B:$P,12,FALSE()),0) -> 0 | T15: =+R15-S15 -> 0 | U15: =IFERROR(VLOOKUP("16_"&A15,SyS!$B:$P,10,FALSE()),0) -> 0 | V15: =IFERROR(VLOOKUP("16_"&A15,SyS!$B:$P,12,FALSE()),0) -> 0 | W15: =+U15-V15 -> 0 | X15: =IFERROR(VLOOKUP("13_"&A15,SyS!$B:$P,10,FALSE()),0) -> 0 | Y15: =IFERROR(VLOOKUP("13_"&A15,SyS!$B:$P,12,FALSE()),0) -> 0 | Z15: =+X15-Y15 -> 0 | AA15: =IFERROR(VLOOKUP("17_"&A15,SyS!$B:$P,10,FALSE()),0) -> 0 | AB15: =IFERROR(VLOOKUP("17_"&A15,SyS!$B:$P,12,FALSE()),0) -> 0 | AC15: =+AA15-AB15 -> 0 | AG15: =IFERROR(VLOOKUP("19_"&A15,SyS!$B:$P,10,FALSE()),0) -> 0 | AH15: =IFERROR(VLOOKUP("19_"&A15,SyS!$B:$P,12,FALSE()),0) -> 0 | AI15: =+AG15-AH15 -> 0 | AM15: =IFERROR(VLOOKUP("23_"&A15,SyS!$B:$P,10,FALSE()),0) -> 0 | AN15: =IFERROR(VLOOKUP("23_"&A15,SyS!$B:$P,12,FALSE()),0) -> 0 | AO15: =+AM15-AN15 -> 0 | BK15: =IFERROR(VLOOKUP("29_"&A15,SyS!$B:$P,10,FALSE()),0) -> 0 | BL15: =IFERROR(VLOOKUP("29_"&A15,SyS!$B:$P,12,FALSE()),0) -> 0 | BM15: =+BK15-BL15 -> 0 | BN15: =IFERROR(VLOOKUP("30_"&A15,SyS!$B:$P,10,FALSE()),0) -> 0 | BO15: =IFERROR(VLOOKUP("30_"&A15,SyS!$B:$P,12,FALSE()),0) -> 0 | BP15: =+BN15-BO15 -> 0 | BQ15: =+E15+H15+K15+Q15+T15+W15+Z15+AC15+AF15+AI15+AL15+AO15+AR15+AU15+AX15+BA15+BD15+BG15+BJ15+BM15+BP15 -> 0
A16: 42102000 | B16: Honorarios profesionales | C16: =IFERROR(VLOOKUP("1_"&A16,SyS!$B:$P,10,FALSE()),0) -> 0 | D16: =IFERROR(VLOOKUP("1_"&A16,SyS!$B:$P,12,FALSE()),0) -> 0 | E16: =+C16-D16 -> 0 | F16: =IFERROR(VLOOKUP("2_"&A16,SyS!$B:$P,10,FALSE()),0) -> 0 | G16: =IFERROR(VLOOKUP("2_"&A16,SyS!$B:$P,12,FALSE()),0) -> 0 | H16: =+F16-G16 -> 0 | O16: =IFERROR(VLOOKUP("14_"&A16,SyS!$B:$P,10,FALSE()),0) -> 0 | P16: =IFERROR(VLOOKUP("14_"&A16,SyS!$B:$P,12,FALSE()),0) -> 0 | Q16: =+O16-P16 -> 0 | R16: =IFERROR(VLOOKUP("15_"&A16,SyS!$B:$P,10,FALSE()),0) -> 0 | S16: =IFERROR(VLOOKUP("15_"&A16,SyS!$B:$P,12,FALSE()),0) -> 0 | T16: =+R16-S16 -> 0 | U16: =IFERROR(VLOOKUP("16_"&A16,SyS!$B:$P,10,FALSE()),0) -> 0 | V16: =IFERROR(VLOOKUP("16_"&A16,SyS!$B:$P,12,FALSE()),0) -> 0 | W16: =+U16-V16 -> 0 | X16: =IFERROR(VLOOKUP("13_"&A16,SyS!$B:$P,10,FALSE()),0) -> 0 | Y16: =IFERROR(VLOOKUP("13_"&A16,SyS!$B:$P,12,FALSE()),0) -> 0 | Z16: =+X16-Y16 -> 0 | AA16: =IFERROR(VLOOKUP("17_"&A16,SyS!$B:$P,10,FALSE()),0) -> 0 | AB16: =IFERROR(VLOOKUP("17_"&A16,SyS!$B:$P,12,FALSE()),0) -> 0 | AC16: =+AA16-AB16 -> 0 | AG16: =IFERROR(VLOOKUP("19_"&A16,SyS!$B:$P,10,FALSE()),0) -> 0 | AH16: =IFERROR(VLOOKUP("19_"&A16,SyS!$B:$P,12,FALSE()),0) -> 0 | AI16: =+AG16-AH16 -> 0 | AM16: =IFERROR(VLOOKUP("23_"&A16,SyS!$B:$P,10,FALSE()),0) -> 0 | AN16: =IFERROR(VLOOKUP("23_"&A16,SyS!$B:$P,12,FALSE()),0) -> 0 | AO16: =+AM16-AN16 -> 0 | BK16: =IFERROR(VLOOKUP("29_"&A16,SyS!$B:$P,10,FALSE()),0) -> 0 | BL16: =IFERROR(VLOOKUP("29_"&A16,SyS!$B:$P,12,FALSE()),0) -> 0 | BM16: =+BK16-BL16 -> 0 | BN16: =IFERROR(VLOOKUP("30_"&A16,SyS!$B:$P,10,FALSE()),0) -> 0 | BO16: =IFERROR(VLOOKUP("30_"&A16,SyS!$B:$P,12,FALSE()),0) -> 0 | BP16: =+BN16-BO16 -> 0 | BQ16: =+E16+H16+K16+Q16+T16+W16+Z16+AC16+AF16+AI16+AL16+AO16+AR16+AU16+AX16+BA16+BD16+BG16+BJ16+BM16+BP16 -> 0
A17: 421030000 | B17: Iva credito fiscal no computable | C17: =IFERROR(VLOOKUP("1_"&A17,SyS!$B:$P,10,FALSE()),0) -> 1238.25 | D17: =IFERROR(VLOOKUP("1_"&A17,SyS!$B:$P,12,FALSE()),0) -> 0 | E17: =+C17-D17 -> 1238.25 | F17: =IFERROR(VLOOKUP("2_"&A17,SyS!$B:$P,10,FALSE()),0) -> 0 | G17: =IFERROR(VLOOKUP("2_"&A17,SyS!$B:$P,12,FALSE()),0) -> 0 | H17: =+F17-G17 -> 0 | O17: =IFERROR(VLOOKUP("14_"&A17,SyS!$B:$P,10,FALSE()),0) -> 0 | P17: =IFERROR(VLOOKUP("14_"&A17,SyS!$B:$P,12,FALSE()),0) -> 0 | Q17: =+O17-P17 -> 0 | R17: =IFERROR(VLOOKUP("15_"&A17,SyS!$B:$P,10,FALSE()),0) -> 0 | S17: =IFERROR(VLOOKUP("15_"&A17,SyS!$B:$P,12,FALSE()),0) -> 0 | T17: =+R17-S17 -> 0 | U17: =IFERROR(VLOOKUP("16_"&A17,SyS!$B:$P,10,FALSE()),0) -> 0 | V17: =IFERROR(VLOOKUP("16_"&A17,SyS!$B:$P,12,FALSE()),0) -> 0 | W17: =+U17-V17 -> 0 | X17: =IFERROR(VLOOKUP("13_"&A17,SyS!$B:$P,10,FALSE()),0) -> 0 | Y17: =IFERROR(VLOOKUP("13_"&A17,SyS!$B:$P,12,FALSE()),0) -> 0 | Z17: =+X17-Y17 -> 0 | AA17: =IFERROR(VLOOKUP("17_"&A17,SyS!$B:$P,10,FALSE()),0) -> 0 | AB17: =IFERROR(VLOOKUP("17_"&A17,SyS!$B:$P,12,FALSE()),0) -> 0 | AC17: =+AA17-AB17 -> 0 | AG17: =IFERROR(VLOOKUP("19_"&A17,SyS!$B:$P,10,FALSE()),0) -> 0 | AH17: =IFERROR(VLOOKUP("19_"&A17,SyS!$B:$P,12,FALSE()),0) -> 0 | AI17: =+AG17-AH17 -> 0 | AM17: =IFERROR(VLOOKUP("23_"&A17,SyS!$B:$P,10,FALSE()),0) -> 0 | AN17: =IFERROR(VLOOKUP("23_"&A17,SyS!$B:$P,12,FALSE()),0) -> 0 | AO17: =+AM17-AN17 -> 0 | BK17: =IFERROR(VLOOKUP("29_"&A17,SyS!$B:$P,10,FALSE()),0) -> 0 | BL17: =IFERROR(VLOOKUP("29_"&A17,SyS!$B:$P,12,FALSE()),0) -> 0 | BM17: =+BK17-BL17 -> 0 | BN17: =IFERROR(VLOOKUP("30_"&A17,SyS!$B:$P,10,FALSE()),0) -> 0 | BO17: =IFERROR(VLOOKUP("30_"&A17,SyS!$B:$P,12,FALSE()),0) -> 0 | BP17: =+BN17-BO17 -> 0 | BQ17: =+E17+H17+K17+Q17+T17+W17+Z17+AC17+AF17+AI17+AL17+AO17+AR17+AU17+AX17+BA17+BD17+BG17+BJ17+BM17+BP17 -> 1238.25
A18: 42104000 | B18: Alquileres | C18: =IFERROR(VLOOKUP("1_"&A18,SyS!$B:$P,10,FALSE()),0) -> 0 | D18: =IFERROR(VLOOKUP("1_"&A18,SyS!$B:$P,12,FALSE()),0) -> 0 | E18: =+C18-D18 -> 0 | F18: =IFERROR(VLOOKUP("2_"&A18,SyS!$B:$P,10,FALSE()),0) -> 0 | G18: =IFERROR(VLOOKUP("2_"&A18,SyS!$B:$P,12,FALSE()),0) -> 0 | H18: =+F18-G18 -> 0 | O18: =IFERROR(VLOOKUP("14_"&A18,SyS!$B:$P,10,FALSE()),0) -> 0 | P18: =IFERROR(VLOOKUP("14_"&A18,SyS!$B:$P,12,FALSE()),0) -> 0 | Q18: =+O18-P18 -> 0 | R18: =IFERROR(VLOOKUP("15_"&A18,SyS!$B:$P,10,FALSE()),0) -> 0 | S18: =IFERROR(VLOOKUP("15_"&A18,SyS!$B:$P,12,FALSE()),0) -> 0 | T18: =+R18-S18 -> 0 | U18: =IFERROR(VLOOKUP("16_"&A18,SyS!$B:$P,10,FALSE()),0) -> 0 | V18: =IFERROR(VLOOKUP("16_"&A18,SyS!$B:$P,12,FALSE()),0) -> 0 | W18: =+U18-V18 -> 0 | X18: =IFERROR(VLOOKUP("13_"&A18,SyS!$B:$P,10,FALSE()),0) -> 0 | Y18: =IFERROR(VLOOKUP("13_"&A18,SyS!$B:$P,12,FALSE()),0) -> 0 | Z18: =+X18-Y18 -> 0 | AA18: =IFERROR(VLOOKUP("17_"&A18,SyS!$B:$P,10,FALSE()),0) -> 0 | AB18: =IFERROR(VLOOKUP("17_"&A18,SyS!$B:$P,12,FALSE()),0) -> 0 | AC18: =+AA18-AB18 -> 0 | AG18: =IFERROR(VLOOKUP("19_"&A18,SyS!$B:$P,10,FALSE()),0) -> 0 | AH18: =IFERROR(VLOOKUP("19_"&A18,SyS!$B:$P,12,FALSE()),0) -> 0 | AI18: =+AG18-AH18 -> 0 | AM18: =IFERROR(VLOOKUP("23_"&A18,SyS!$B:$P,10,FALSE()),0) -> 0 | AN18: =IFERROR(VLOOKUP("23_"&A18,SyS!$B:$P,12,FALSE()),0) -> 0 | AO18: =+AM18-AN18 -> 0 | BK18: =IFERROR(VLOOKUP("29_"&A18,SyS!$B:$P,10,FALSE()),0) -> 0 | BL18: =IFERROR(VLOOKUP("29_"&A18,SyS!$B:$P,12,FALSE()),0) -> 0 | BM18: =+BK18-BL18 -> 0 | BN18: =IFERROR(VLOOKUP("30_"&A18,SyS!$B:$P,10,FALSE()),0) -> 0 | BO18: =IFERROR(VLOOKUP("30_"&A18,SyS!$B:$P,12,FALSE()),0) -> 0 | BP18: =+BN18-BO18 -> 0 | BQ18: =+E18+H18+K18+Q18+T18+W18+Z18+AC18+AF18+AI18+AL18+AO18+AR18+AU18+AX18+BA18+BD18+BG18+BJ18+BM18+BP18 -> 0
... A121: 432010000 | B121: ROBO | C121: =IFERROR(VLOOKUP("1_"&A121,SyS!$B:$P,10,FALSE()),0) -> 0 | D121: =IFERROR(VLOOKUP("1_"&A121,SyS!$B:$P,12,FALSE()),0) -> 0 | E121: =+C121-D121 -> 0 | F121: =IFERROR(VLOOKUP("2_"&A121,SyS!$B:$P,10,FALSE()),0) -> 0 | G121: =IFERROR(VLOOKUP("2_"&A121,SyS!$B:$P,12,FALSE()),0) -> 0 | H121: =+F121-G121 -> 0 | O121: =IFERROR(VLOOKUP("14_"&A121,SyS!$B:$P,10,FALSE()),0) -> 0 | P121: =IFERROR(VLOOKUP("14_"&A121,SyS!$B:$P,12,FALSE()),0) -> 0 | Q121: =+O121-P121 -> 0 | R121: =IFERROR(VLOOKUP("15_"&A121,SyS!$B:$P,10,FALSE()),0) -> 0 | S121: =IFERROR(VLOOKUP("15_"&A121,SyS!$B:$P,12,FALSE()),0) -> 0 | T121: =+R121-S121 -> 0 | U121: =IFERROR(VLOOKUP("16_"&A121,SyS!$B:$P,10,FALSE()),0) -> 0 | V121: =IFERROR(VLOOKUP("16_"&A121,SyS!$B:$P,12,FALSE()),0) -> 0 | W121: =+U121-V121 -> 0 | X121: =IFERROR(VLOOKUP("13_"&A121,SyS!$B:$P,10,FALSE()),0) -> 0 | Y121: =IFERROR(VLOOKUP("13_"&A121,SyS!$B:$P,12,FALSE()),0) -> 0 | Z121: =+X121-Y121 -> 0 | AA121: =IFERROR(VLOOKUP("17_"&A121,SyS!$B:$P,10,FALSE()),0) -> 0 | AB121: =IFERROR(VLOOKUP("17_"&A121,SyS!$B:$P,12,FALSE()),0) -> 0 | AC121: =+AA121-AB121 -> 0 | AG121: =IFERROR(VLOOKUP("19_"&A121,SyS!$B:$P,10,FALSE()),0) -> 0 | AH121: =IFERROR(VLOOKUP("19_"&A121,SyS!$B:$P,12,FALSE()),0) -> 0 | AI121: =+AG121-AH121 -> 0 | AM121: =IFERROR(VLOOKUP("23_"&A121,SyS!$B:$P,10,FALSE()),0) -> 0 | AN121: =IFERROR(VLOOKUP("23_"&A121,SyS!$B:$P,12,FALSE()),0) -> 0 | AO121: =+AM121-AN121 -> 0 | BK121: =IFERROR(VLOOKUP("29_"&A121,SyS!$B:$P,10,FALSE()),0) -> 0 | BL121: =IFERROR(VLOOKUP("29_"&A121,SyS!$B:$P,12,FALSE()),0) -> 0 | BM121: =+BK121-BL121 -> 0 | BN121: =IFERROR(VLOOKUP("30_"&A121,SyS!$B:$P,10,FALSE()),0) -> 0 | BO121: =IFERROR(VLOOKUP("30_"&A121,SyS!$B:$P,12,FALSE()),0) -> 0 | BP121: =+BN121-BO121 -> 0 | BQ121: =+E121+H121+K121+Q121+T121+W121+Z121+AC121+AF121+AI121+AL121+AO121+AR121+AU121+AX121+BA121+BD121+BG121+BJ121+BM121+BP121 -> 0
B122: I - R AMBIENTAL | C122: =IFERROR(VLOOKUP("1_"&A122,SyS!$B:$P,10,FALSE()),0) -> 0 | D122: =IFERROR(VLOOKUP("1_"&A122,SyS!$B:$P,12,FALSE()),0) -> 0 | E122: =+C122-D122 -> 0
A123: 422010000 | B123: TASAS AMBIENTALES I- R. AMBIENTAL | C123: =IFERROR(VLOOKUP("1_"&A123,SyS!$B:$P,10,FALSE()),0) -> 0 | D123: =IFERROR(VLOOKUP("1_"&A123,SyS!$B:$P,12,FALSE()),0) -> 0 | E123: =+C123-D123 -> 0 | F123: =IFERROR(VLOOKUP("2_"&A123,SyS!$B:$P,10,FALSE()),0) -> 0 | G123: =IFERROR(VLOOKUP("2_"&A123,SyS!$B:$P,12,FALSE()),0) -> 0 | H123: =+F123-G123 -> 0 | O123: =IFERROR(VLOOKUP("14_"&A123,SyS!$B:$P,10,FALSE()),0) -> 0 | P123: =IFERROR(VLOOKUP("14_"&A123,SyS!$B:$P,12,FALSE()),0) -> 0 | Q123: =+O123-P123 -> 0 | R123: =IFERROR(VLOOKUP("15_"&A123,SyS!$B:$P,10,FALSE()),0) -> 0 | S123: =IFERROR(VLOOKUP("15_"&A123,SyS!$B:$P,12,FALSE()),0) -> 0 | T123: =+R123-S123 -> 0 | U123: =IFERROR(VLOOKUP("16_"&A123,SyS!$B:$P,10,FALSE()),0) -> 0 | V123: =IFERROR(VLOOKUP("16_"&A123,SyS!$B:$P,12,FALSE()),0) -> 0 | W123: =+U123-V123 -> 0 | X123: =IFERROR(VLOOKUP("13_"&A123,SyS!$B:$P,10,FALSE()),0) -> 0 | Y123: =IFERROR(VLOOKUP("13_"&A123,SyS!$B:$P,12,FALSE()),0) -> 0 | Z123: =+X123-Y123 -> 0 | AA123: =IFERROR(VLOOKUP("17_"&A123,SyS!$B:$P,10,FALSE()),0) -> 0 | AB123: =IFERROR(VLOOKUP("17_"&A123,SyS!$B:$P,12,FALSE()),0) -> 0 | AC123: =+AA123-AB123 -> 0 | AG123: =IFERROR(VLOOKUP("19_"&A123,SyS!$B:$P,10,FALSE()),0) -> 0 | AH123: =IFERROR(VLOOKUP("19_"&A123,SyS!$B:$P,12,FALSE()),0) -> 0 | AI123: =+AG123-AH123 -> 0 | AM123: =IFERROR(VLOOKUP("23_"&A123,SyS!$B:$P,10,FALSE()),0) -> 0 | AN123: =IFERROR(VLOOKUP("23_"&A123,SyS!$B:$P,12,FALSE()),0) -> 0 | AO123: =+AM123-AN123 -> 0 | BK123: =IFERROR(VLOOKUP("29_"&A123,SyS!$B:$P,10,FALSE()),0) -> 0 | BL123: =IFERROR(VLOOKUP("29_"&A123,SyS!$B:$P,12,FALSE()),0) -> 0 | BM123: =+BK123-BL123 -> 0 | BN123: =IFERROR(VLOOKUP("30_"&A123,SyS!$B:$P,10,FALSE()),0) -> 0 | BO123: =IFERROR(VLOOKUP("30_"&A123,SyS!$B:$P,12,FALSE()),0) -> 0 | BP123: =+BN123-BO123 -> 0 | BQ123: =+E123+H123+K123+Q123+T123+W123+Z123+AC123+AF123+AI123+AL123+AO123+AR123+AU123+AX123+BA123+BD123+BG123+BJ123+BM123+BP123 -> 0
A124: 422020000 | B124: Remediación Ambiental I- R. Ambiental | C124: =IFERROR(VLOOKUP("1_"&A124,SyS!$B:$P,10,FALSE()),0) -> 0 | D124: =IFERROR(VLOOKUP("1_"&A124,SyS!$B:$P,12,FALSE()),0) -> 0 | E124: =+C124-D124 -> 0 | F124: =IFERROR(VLOOKUP("2_"&A124,SyS!$B:$P,10,FALSE()),0) -> 0 | G124: =IFERROR(VLOOKUP("2_"&A124,SyS!$B:$P,12,FALSE()),0) -> 0 | H124: =+F124-G124 -> 0 | O124: =IFERROR(VLOOKUP("14_"&A124,SyS!$B:$P,10,FALSE()),0) -> 0 | P124: =IFERROR(VLOOKUP("14_"&A124,SyS!$B:$P,12,FALSE()),0) -> 0 | Q124: =+O124-P124 -> 0 | R124: =IFERROR(VLOOKUP("15_"&A124,SyS!$B:$P,10,FALSE()),0) -> 0 | S124: =IFERROR(VLOOKUP("15_"&A124,SyS!$B:$P,12,FALSE()),0) -> 0 | T124: =+R124-S124 -> 0 | U124: =IFERROR(VLOOKUP("16_"&A124,SyS!$B:$P,10,FALSE()),0) -> 0 | V124: =IFERROR(VLOOKUP("16_"&A124,SyS!$B:$P,12,FALSE()),0) -> 0 | W124: =+U124-V124 -> 0 | X124: =IFERROR(VLOOKUP("13_"&A124,SyS!$B:$P,10,FALSE()),0) -> 0 | Y124: =IFERROR(VLOOKUP("13_"&A124,SyS!$B:$P,12,FALSE()),0) -> 0 | Z124: =+X124-Y124 -> 0 | AA124: =IFERROR(VLOOKUP("17_"&A124,SyS!$B:$P,10,FALSE()),0) -> 0 | AB124: =IFERROR(VLOOKUP("17_"&A124,SyS!$B:$P,12,FALSE()),0) -> 0 | AC124: =+AA124-AB124 -> 0 | AG124: =IFERROR(VLOOKUP("19_"&A124,SyS!$B:$P,10,FALSE()),0) -> 0 | AH124: =IFERROR(VLOOKUP("19_"&A124,SyS!$B:$P,12,FALSE()),0) -> 0 | AI124: =+AG124-AH124 -> 0 | AM124: =IFERROR(VLOOKUP("23_"&A124,SyS!$B:$P,10,FALSE()),0) -> 0 | AN124: =IFERROR(VLOOKUP("23_"&A124,SyS!$B:$P,12,FALSE()),0) -> 0 | AO124: =+AM124-AN124 -> 0 | BK124: =IFERROR(VLOOKUP("29_"&A124,SyS!$B:$P,10,FALSE()),0) -> 0 | BL124: =IFERROR(VLOOKUP("29_"&A124,SyS!$B:$P,12,FALSE()),0) -> 0 | BM124: =+BK124-BL124 -> 0 | BN124: =IFERROR(VLOOKUP("30_"&A124,SyS!$B:$P,10,FALSE()),0) -> 0 | BO124: =IFERROR(VLOOKUP("30_"&A124,SyS!$B:$P,12,FALSE()),0) -> 0 | BP124: =+BN124-BO124 -> 0 | BQ124: =+E124+H124+K124+Q124+T124+W124+Z124+AC124+AF124+AI124+AL124+AO124+AR124+AU124+AX124+BA124+BD124+BG124+BJ124+BM124+BP124 -> 0
A125: 422080000 | B125: Gastos Ferretería I -R.Ambiental | C125: =IFERROR(VLOOKUP("1_"&A125,SyS!$B:$P,10,FALSE()),0) -> 0 | D125: =IFERROR(VLOOKUP("1_"&A125,SyS!$B:$P,12,FALSE()),0) -> 0 | E125: =+C125-D125 -> 0 | F125: =IFERROR(VLOOKUP("2_"&A125,SyS!$B:$P,10,FALSE()),0) -> 0 | G125: =IFERROR(VLOOKUP("2_"&A125,SyS!$B:$P,12,FALSE()),0) -> 0 | H125: =+F125-G125 -> 0 | O125: =IFERROR(VLOOKUP("14_"&A125,SyS!$B:$P,10,FALSE()),0) -> 0 | P125: =IFERROR(VLOOKUP("14_"&A125,SyS!$B:$P,12,FALSE()),0) -> 0 | Q125: =+O125-P125 -> 0 | R125: =IFERROR(VLOOKUP("15_"&A125,SyS!$B:$P,10,FALSE()),0) -> 0 | S125: =IFERROR(VLOOKUP("15_"&A125,SyS!$B:$P,12,FALSE()),0) -> 0 | T125: =+R125-S125 -> 0 | U125: =IFERROR(VLOOKUP("16_"&A125,SyS!$B:$P,10,FALSE()),0) -> 0 | V125: =IFERROR(VLOOKUP("16_"&A125,SyS!$B:$P,12,FALSE()),0) -> 0 | W125: =+U125-V125 -> 0 | X125: =IFERROR(VLOOKUP("13_"&A125,SyS!$B:$P,10,FALSE()),0) -> 0 | Y125: =IFERROR(VLOOKUP("13_"&A125,SyS!$B:$P,12,FALSE()),0) -> 0 | Z125: =+X125-Y125 -> 0 | AA125: =IFERROR(VLOOKUP("17_"&A125,SyS!$B:$P,10,FALSE()),0) -> 0 | AB125: =IFERROR(VLOOKUP("17_"&A125,SyS!$B:$P,12,FALSE()),0) -> 0 | AC125: =+AA125-AB125 -> 0 | AG125: =IFERROR(VLOOKUP("19_"&A125,SyS!$B:$P,10,FALSE()),0) -> 0 | AH125: =IFERROR(VLOOKUP("19_"&A125,SyS!$B:$P,12,FALSE()),0) -> 0 | AI125: =+AG125-AH125 -> 0 | AM125: =IFERROR(VLOOKUP("23_"&A125,SyS!$B:$P,10,FALSE()),0) -> 0 | AN125: =IFERROR(VLOOKUP("23_"&A125,SyS!$B:$P,12,FALSE()),0) -> 0 | AO125: =+AM125-AN125 -> 0 | BK125: =IFERROR(VLOOKUP("29_"&A125,SyS!$B:$P,10,FALSE()),0) -> 0 | BL125: =IFERROR(VLOOKUP("29_"&A125,SyS!$B:$P,12,FALSE()),0) -> 0 | BM125: =+BK125-BL125 -> 0 | BN125: =IFERROR(VLOOKUP("30_"&A125,SyS!$B:$P,10,FALSE()),0) -> 0 | BO125: =IFERROR(VLOOKUP("30_"&A125,SyS!$B:$P,12,FALSE()),0) -> 0 | BP125: =+BN125-BO125 -> 0 | BQ125: =+E125+H125+K125+Q125+T125+W125+Z125+AC125+AF125+AI125+AL125+AO125+AR125+AU125+AX125+BA125+BD125+BG125+BJ125+BM125+BP125 -> 0
A126: 422220000 | B126: Análisis Muestras -R. Ambiental | C126: =IFERROR(VLOOKUP("1_"&A126,SyS!$B:$P,10,FALSE()),0) -> 0 | D126: =IFERROR(VLOOKUP("1_"&A126,SyS!$B:$P,12,FALSE()),0) -> 0 | E126: =+C126-D126 -> 0 | F126: =IFERROR(VLOOKUP("2_"&A126,SyS!$B:$P,10,FALSE()),0) -> 0 | G126: =IFERROR(VLOOKUP("2_"&A126,SyS!$B:$P,12,FALSE()),0) -> 0 | H126: =+F126-G126 -> 0 | O126: =IFERROR(VLOOKUP("14_"&A126,SyS!$B:$P,10,FALSE()),0) -> 0 | P126: =IFERROR(VLOOKUP("14_"&A126,SyS!$B:$P,12,FALSE()),0) -> 0 | Q126: =+O126-P126 -> 0 | R126: =IFERROR(VLOOKUP("15_"&A126,SyS!$B:$P,10,FALSE()),0) -> 0 | S126: =IFERROR(VLOOKUP("15_"&A126,SyS!$B:$P,12,FALSE()),0) -> 0 | T126: =+R126-S126 -> 0 | U126: =IFERROR(VLOOKUP("16_"&A126,SyS!$B:$P,10,FALSE()),0) -> 0 | V126: =IFERROR(VLOOKUP("16_"&A126,SyS!$B:$P,12,FALSE()),0) -> 0 | W126: =+U126-V126 -> 0 | X126: =IFERROR(VLOOKUP("13_"&A126,SyS!$B:$P,10,FALSE()),0) -> 0 | Y126: =IFERROR(VLOOKUP("13_"&A126,SyS!$B:$P,12,FALSE()),0) -> 0 | Z126: =+X126-Y126 -> 0 | AA126: =IFERROR(VLOOKUP("17_"&A126,SyS!$B:$P,10,FALSE()),0) -> 0 | AB126: =IFERROR(VLOOKUP("17_"&A126,SyS!$B:$P,12,FALSE()),0) -> 0 | AC126: =+AA126-AB126 -> 0 | AG126: =IFERROR(VLOOKUP("19_"&A126,SyS!$B:$P,10,FALSE()),0) -> 0 | AH126: =IFERROR(VLOOKUP("19_"&A126,SyS!$B:$P,12,FALSE()),0) -> 0 | AI126: =+AG126-AH126 -> 0 | AM126: =IFERROR(VLOOKUP("23_"&A126,SyS!$B:$P,10,FALSE()),0) -> 0 | AN126: =IFERROR(VLOOKUP("23_"&A126,SyS!$B:$P,12,FALSE()),0) -> 0 | AO126: =+AM126-AN126 -> 0 | BK126: =IFERROR(VLOOKUP("29_"&A126,SyS!$B:$P,10,FALSE()),0) -> 0 | BL126: =IFERROR(VLOOKUP("29_"&A126,SyS!$B:$P,12,FALSE()),0) -> 0 | BM126: =+BK126-BL126 -> 0 | BN126: =IFERROR(VLOOKUP("30_"&A126,SyS!$B:$P,10,FALSE()),0) -> 0 | BO126: =IFERROR(VLOOKUP("30_"&A126,SyS!$B:$P,12,FALSE()),0) -> 0 | BP126: =+BN126-BO126 -> 0 | BQ126: =+E126+H126+K126+Q126+T126+W126+Z126+AC126+AF126+AI126+AL126+AO126+AR126+AU126+AX126+BA126+BD126+BG126+BJ126+BM126+BP126 -> 0
A127: 421470000 | B127: Análisis Muestras I - R. Ambiental Catamarca | C127: =IFERROR(VLOOKUP("1_"&A127,SyS!$B:$P,10,FALSE()),0) -> 0 | D127: =IFERROR(VLOOKUP("1_"&A127,SyS!$B:$P,12,FALSE()),0) -> 0 | E127: =+C127-D127 -> 0 | F127: =IFERROR(VLOOKUP("2_"&A127,SyS!$B:$P,10,FALSE()),0) -> 0 | G127: =IFERROR(VLOOKUP("2_"&A127,SyS!$B:$P,12,FALSE()),0) -> 0 | H127: =+F127-G127 -> 0 | O127: =IFERROR(VLOOKUP("14_"&A127,SyS!$B:$P,10,FALSE()),0) -> 0 | P127: =IFERROR(VLOOKUP("14_"&A127,SyS!$B:$P,12,FALSE()),0) -> 0 | Q127: =+O127-P127 -> 0 | R127: =IFERROR(VLOOKUP("15_"&A127,SyS!$B:$P,10,FALSE()),0) -> 0 | S127: =IFERROR(VLOOKUP("15_"&A127,SyS!$B:$P,12,FALSE()),0) -> 0 | T127: =+R127-S127 -> 0 | U127: =IFERROR(VLOOKUP("16_"&A127,SyS!$B:$P,10,FALSE()),0) -> 0 | V127: =IFERROR(VLOOKUP("16_"&A127,SyS!$B:$P,12,FALSE()),0) -> 0 | W127: =+U127-V127 -> 0 | X127: =IFERROR(VLOOKUP("13_"&A127,SyS!$B:$P,10,FALSE()),0) -> 0 | Y127: =IFERROR(VLOOKUP("13_"&A127,SyS!$B:$P,12,FALSE()),0) -> 0 | Z127: =+X127-Y127 -> 0 | AA127: =IFERROR(VLOOKUP("17_"&A127,SyS!$B:$P,10,FALSE()),0) -> 0 | AB127: =IFERROR(VLOOKUP("17_"&A127,SyS!$B:$P,12,FALSE()),0) -> 0 | AC127: =+AA127-AB127 -> 0 | AG127: =IFERROR(VLOOKUP("19_"&A127,SyS!$B:$P,10,FALSE()),0) -> 0 | AH127: =IFERROR(VLOOKUP("19_"&A127,SyS!$B:$P,12,FALSE()),0) -> 0 | AI127: =+AG127-AH127 -> 0 | AM127: =IFERROR(VLOOKUP("23_"&A127,SyS!$B:$P,10,FALSE()),0) -> 0 | AN127: =IFERROR(VLOOKUP("23_"&A127,SyS!$B:$P,12,FALSE()),0) -> 0 | AO127: =+AM127-AN127 -> 0 | BK127: =IFERROR(VLOOKUP("29_"&A127,SyS!$B:$P,10,FALSE()),0) -> 0 | BL127: =IFERROR(VLOOKUP("29_"&A127,SyS!$B:$P,12,FALSE()),0) -> 0 | BM127: =+BK127-BL127 -> 0 | BN127: =IFERROR(VLOOKUP("30_"&A127,SyS!$B:$P,10,FALSE()),0) -> 0 | BO127: =IFERROR(VLOOKUP("30_"&A127,SyS!$B:$P,12,FALSE()),0) -> 0 | BP127: =+BN127-BO127 -> 0 | BQ127: =+E127+H127+K127+Q127+T127+W127+Z127+AC127+AF127+AI127+AL127+AO127+AR127+AU127+AX127+BA127+BD127+BG127+BJ127+BM127+BP127 -> 0
A128: 422090000 | B128: Gs en personal R- Ambiental | C128: =IFERROR(VLOOKUP("1_"&A128,SyS!$B:$P,10,FALSE()),0) -> 0 | D128: =IFERROR(VLOOKUP("1_"&A128,SyS!$B:$P,12,FALSE()),0) -> 0 | E128: =+C128-D128 -> 0 | F128: =IFERROR(VLOOKUP("2_"&A128,SyS!$B:$P,10,FALSE()),0) -> 0 | G128: =IFERROR(VLOOKUP("2_"&A128,SyS!$B:$P,12,FALSE()),0) -> 0 | H128: =+F128-G128 -> 0 | O128: =IFERROR(VLOOKUP("14_"&A128,SyS!$B:$P,10,FALSE()),0) -> 0 | P128: =IFERROR(VLOOKUP("14_"&A128,SyS!$B:$P,12,FALSE()),0) -> 0 | Q128: =+O128-P128 -> 0 | R128: =IFERROR(VLOOKUP("15_"&A128,SyS!$B:$P,10,FALSE()),0) -> 0 | S128: =IFERROR(VLOOKUP("15_"&A128,SyS!$B:$P,12,FALSE()),0) -> 0 | T128: =+R128-S128 -> 0 | U128: =IFERROR(VLOOKUP("16_"&A128,SyS!$B:$P,10,FALSE()),0) -> 0 | V128: =IFERROR(VLOOKUP("16_"&A128,SyS!$B:$P,12,FALSE()),0) -> 0 | W128: =+U128-V128 -> 0 | X128: =IFERROR(VLOOKUP("13_"&A128,SyS!$B:$P,10,FALSE()),0) -> 0 | Y128: =IFERROR(VLOOKUP("13_"&A128,SyS!$B:$P,12,FALSE()),0) -> 0 | Z128: =+X128-Y128 -> 0 | AA128: =IFERROR(VLOOKUP("17_"&A128,SyS!$B:$P,10,FALSE()),0) -> 0 | AB128: =IFERROR(VLOOKUP("17_"&A128,SyS!$B:$P,12,FALSE()),0) -> 0 | AC128: =+AA128-AB128 -> 0 | AG128: =IFERROR(VLOOKUP("19_"&A128,SyS!$B:$P,10,FALSE()),0) -> 0 | AH128: =IFERROR(VLOOKUP("19_"&A128,SyS!$B:$P,12,FALSE()),0) -> 0 | AI128: =+AG128-AH128 -> 0 | AM128: =IFERROR(VLOOKUP("23_"&A128,SyS!$B:$P,10,FALSE()),0) -> 0 | AN128: =IFERROR(VLOOKUP("23_"&A128,SyS!$B:$P,12,FALSE()),0) -> 0 | AO128: =+AM128-AN128 -> 0 | BK128: =IFERROR(VLOOKUP("29_"&A128,SyS!$B:$P,10,FALSE()),0) -> 0 | BL128: =IFERROR(VLOOKUP("29_"&A128,SyS!$B:$P,12,FALSE()),0) -> 0 | BM128: =+BK128-BL128 -> 0 | BN128: =IFERROR(VLOOKUP("30_"&A128,SyS!$B:$P,10,FALSE()),0) -> 0 | BO128: =IFERROR(VLOOKUP("30_"&A128,SyS!$B:$P,12,FALSE()),0) -> 0 | BP128: =+BN128-BO128 -> 0 | BQ128: =+E128+H128+K128+Q128+T128+W128+Z128+AC128+AF128+AI128+AL128+AO128+AR128+AU128+AX128+BA128+BD128+BG128+BJ128+BM128+BP128 -> 0
A129: 422240000 | B129: Honorarios profesionales - Remediación ambiental | C129: =IFERROR(VLOOKUP("1_"&A129,SyS!$B:$P,10,FALSE()),0) -> 0 | D129: =IFERROR(VLOOKUP("1_"&A129,SyS!$B:$P,12,FALSE()),0) -> 0 | E129: =+C129-D129 -> 0 | F129: =IFERROR(VLOOKUP("2_"&A129,SyS!$B:$P,10,FALSE()),0) -> 0 | G129: =IFERROR(VLOOKUP("2_"&A129,SyS!$B:$P,12,FALSE()),0) -> 0 | H129: =+F129-G129 -> 0 | O129: =IFERROR(VLOOKUP("14_"&A129,SyS!$B:$P,10,FALSE()),0) -> 0 | P129: =IFERROR(VLOOKUP("14_"&A129,SyS!$B:$P,12,FALSE()),0) -> 0 | Q129: =+O129-P129 -> 0 | R129: =IFERROR(VLOOKUP("15_"&A129,SyS!$B:$P,10,FALSE()),0) -> 0 | S129: =IFERROR(VLOOKUP("15_"&A129,SyS!$B:$P,12,FALSE()),0) -> 0 | T129: =+R129-S129 -> 0 | U129: =IFERROR(VLOOKUP("16_"&A129,SyS!$B:$P,10,FALSE()),0) -> 0 | V129: =IFERROR(VLOOKUP("16_"&A129,SyS!$B:$P,12,FALSE()),0) -> 0 | W129: =+U129-V129 -> 0 | X129: =IFERROR(VLOOKUP("13_"&A129,SyS!$B:$P,10,FALSE()),0) -> 0 | Y129: =IFERROR(VLOOKUP("13_"&A129,SyS!$B:$P,12,FALSE()),0) -> 0 | Z129: =+X129-Y129 -> 0 | AA129: =IFERROR(VLOOKUP("17_"&A129,SyS!$B:$P,10,FALSE()),0) -> 0 | AB129: =IFERROR(VLOOKUP("17_"&A129,SyS!$B:$P,12,FALSE()),0) -> 0 | AC129: =+AA129-AB129 -> 0 | AG129: =IFERROR(VLOOKUP("19_"&A129,SyS!$B:$P,10,FALSE()),0) -> 0 | AH129: =IFERROR(VLOOKUP("19_"&A129,SyS!$B:$P,12,FALSE()),0) -> 0 | AI129: =+AG129-AH129 -> 0 | AM129: =IFERROR(VLOOKUP("23_"&A129,SyS!$B:$P,10,FALSE()),0) -> 0 | AN129: =IFERROR(VLOOKUP("23_"&A129,SyS!$B:$P,12,FALSE()),0) -> 0 | AO129: =+AM129-AN129 -> 0 | BK129: =IFERROR(VLOOKUP("29_"&A129,SyS!$B:$P,10,FALSE()),0) -> 0 | BL129: =IFERROR(VLOOKUP("29_"&A129,SyS!$B:$P,12,FALSE()),0) -> 0 | BM129: =+BK129-BL129 -> 0 | BN129: =IFERROR(VLOOKUP("30_"&A129,SyS!$B:$P,10,FALSE()),0) -> 0 | BO129: =IFERROR(VLOOKUP("30_"&A129,SyS!$B:$P,12,FALSE()),0) -> 0 | BP129: =+BN129-BO129 -> 0 | BQ129: =+E129+H129+K129+Q129+T129+W129+Z129+AC129+AF129+AI129+AL129+AO129+AR129+AU129+AX129+BA129+BD129+BG129+BJ129+BM129+BP129 -> 0
B130: ADMINISTRACION GENERAL | C130: =IFERROR(VLOOKUP("1_"&A130,SyS!$B:$P,10,FALSE()),0) -> 0 | D130: =IFERROR(VLOOKUP("1_"&A130,SyS!$B:$P,12,FALSE()),0) -> 0 | E130: =+C130-D130 -> 0
A131: 425110000 | B131: REFRIGERIOS ADM. GRAL. | C131: =IFERROR(VLOOKUP("1_"&A131,SyS!$B:$P,10,FALSE()),0) -> 0 | D131: =IFERROR(VLOOKUP("1_"&A131,SyS!$B:$P,12,FALSE()),0) -> 0 | E131: =+C131-D131 -> 0 | F131: =IFERROR(VLOOKUP("2_"&A131,SyS!$B:$P,10,FALSE()),0) -> 634.65 | G131: =IFERROR(VLOOKUP("2_"&A131,SyS!$B:$P,12,FALSE()),0) -> 0 | H131: =+F131-G131 -> 634.65 | O131: =IFERROR(VLOOKUP("14_"&A131,SyS!$B:$P,10,FALSE()),0) -> 0 | P131: =IFERROR(VLOOKUP("14_"&A131,SyS!$B:$P,12,FALSE()),0) -> 0 | Q131: =+O131-P131 -> 0 | R131: =IFERROR(VLOOKUP("15_"&A131,SyS!$B:$P,10,FALSE()),0) -> 0 | S131: =IFERROR(VLOOKUP("15_"&A131,SyS!$B:$P,12,FALSE()),0) -> 0 | T131: =+R131-S131 -> 0 | U131: =IFERROR(VLOOKUP("16_"&A131,SyS!$B:$P,10,FALSE()),0) -> 0 | V131: =IFERROR(VLOOKUP("16_"&A131,SyS!$B:$P,12,FALSE()),0) -> 0 | W131: =+U131-V131 -> 0 | X131: =IFERROR(VLOOKUP("13_"&A131,SyS!$B:$P,10,FALSE()),0) -> 0 | Y131: =IFERROR(VLOOKUP("13_"&A131,SyS!$B:$P,12,FALSE()),0) -> 0 | Z131: =+X131-Y131 -> 0 | AA131: =IFERROR(VLOOKUP("17_"&A131,SyS!$B:$P,10,FALSE()),0) -> 0 | AB131: =IFERROR(VLOOKUP("17_"&A131,SyS!$B:$P,12,FALSE()),0) -> 0 | AC131: =+AA131-AB131 -> 0 | AG131: =IFERROR(VLOOKUP("19_"&A131,SyS!$B:$P,10,FALSE()),0) -> 0 | AH131: =IFERROR(VLOOKUP("19_"&A131,SyS!$B:$P,12,FALSE()),0) -> 0 | AI131: =+AG131-AH131 -> 0 | AM131: =IFERROR(VLOOKUP("23_"&A131,SyS!$B:$P,10,FALSE()),0) -> 0 | AN131: =IFERROR(VLOOKUP("23_"&A131,SyS!$B:$P,12,FALSE()),0) -> 0 | AO131: =+AM131-AN131 -> 0 | BK131: =IFERROR(VLOOKUP("29_"&A131,SyS!$B:$P,10,FALSE()),0) -> 0 | BL131: =IFERROR(VLOOKUP("29_"&A131,SyS!$B:$P,12,FALSE()),0) -> 0 | BM131: =+BK131-BL131 -> 0 | BN131: =IFERROR(VLOOKUP("30_"&A131,SyS!$B:$P,10,FALSE()),0) -> 0 | BO131: =IFERROR(VLOOKUP("30_"&A131,SyS!$B:$P,12,FALSE()),0) -> 0 | BP131: =+BN131-BO131 -> 0 | BQ131: =+E131+H131+K131+Q131+T131+W131+Z131+AC131+AF131+AI131+AL131+AO131+AR131+AU131+AX131+BA131+BD131+BG131+BJ131+BM131+BP131 -> 634.65
A132: 425120000 | B132: MOVILIDAD Y VIATICOS ADM GENERAL | C132: =IFERROR(VLOOKUP("1_"&A132,SyS!$B:$P,10,FALSE()),0) -> 0 | D132: =IFERROR(VLOOKUP("1_"&A132,SyS!$B:$P,12,FALSE()),0) -> 0 | E132: =+C132-D132 -> 0 | F132: =IFERROR(VLOOKUP("2_"&A132,SyS!$B:$P,10,FALSE()),0) -> 123.47 | G132: =IFERROR(VLOOKUP("2_"&A132,SyS!$B:$P,12,FALSE()),0) -> 0 | H132: =+F132-G132 -> 123.47 | O132: =IFERROR(VLOOKUP("14_"&A132,SyS!$B:$P,10,FALSE()),0) -> 0 | P132: =IFERROR(VLOOKUP("14_"&A132,SyS!$B:$P,12,FALSE()),0) -> 0 | Q132: =+O132-P132 -> 0 | R132: =IFERROR(VLOOKUP("15_"&A132,SyS!$B:$P,10,FALSE()),0) -> 0 | S132: =IFERROR(VLOOKUP("15_"&A132,SyS!$B:$P,12,FALSE()),0) -> 0 | T132: =+R132-S132 -> 0 | U132: =IFERROR(VLOOKUP("16_"&A132,SyS!$B:$P,10,FALSE()),0) -> 0 | V132: =IFERROR(VLOOKUP("16_"&A132,SyS!$B:$P,12,FALSE()),0) -> 0 | W132: =+U132-V132 -> 0 | X132: =IFERROR(VLOOKUP("13_"&A132,SyS!$B:$P,10,FALSE()),0) -> 0 | Y132: =IFERROR(VLOOKUP("13_"&A132,SyS!$B:$P,12,FALSE()),0) -> 0 | Z132: =+X132-Y132 -> 0 | AA132: =IFERROR(VLOOKUP("17_"&A132,SyS!$B:$P,10,FALSE()),0) -> 0 | AB132: =IFERROR(VLOOKUP("17_"&A132,SyS!$B:$P,12,FALSE()),0) -> 0 | AC132: =+AA132-AB132 -> 0 | AG132: =IFERROR(VLOOKUP("19_"&A132,SyS!$B:$P,10,FALSE()),0) -> 0 | AH132: =IFERROR(VLOOKUP("19_"&A132,SyS!$B:$P,12,FALSE()),0) -> 0 | AI132: =+AG132-AH132 -> 0 | AM132: =IFERROR(VLOOKUP("23_"&A132,SyS!$B:$P,10,FALSE()),0) -> 0 | AN132: =IFERROR(VLOOKUP("23_"&A132,SyS!$B:$P,12,FALSE()),0) -> 0 | AO132: =+AM132-AN132 -> 0 | BK132: =IFERROR(VLOOKUP("29_"&A132,SyS!$B:$P,10,FALSE()),0) -> 0 | BL132: =IFERROR(VLOOKUP("29_"&A132,SyS!$B:$P,12,FALSE()),0) -> 0 | BM132: =+BK132-BL132 -> 0 | BN132: =IFERROR(VLOOKUP("30_"&A132,SyS!$B:$P,10,FALSE()),0) -> 0 | BO132: =IFERROR(VLOOKUP("30_"&A132,SyS!$B:$P,12,FALSE()),0) -> 0 | BP132: =+BN132-BO132 -> 0 | BQ132: =+E132+H132+K132+Q132+T132+W132+Z132+AC132+AF132+AI132+AL132+AO132+AR132+AU132+AX132+BA132+BD132+BG132+BJ132+BM132+BP132 -> 123.47
A133: 425130000 | B133: EXPENSAS DEPTO GEOLOGOS ADM GRAL | C133: =IFERROR(VLOOKUP("1_"&A133,SyS!$B:$P,10,FALSE()),0) -> 0 | D133: =IFERROR(VLOOKUP("1_"&A133,SyS!$B:$P,12,FALSE()),0) -> 0 | E133: =+C133-D133 -> 0 | F133: =IFERROR(VLOOKUP("2_"&A133,SyS!$B:$P,10,FALSE()),0) -> 0 | G133: =IFERROR(VLOOKUP("2_"&A133,SyS!$B:$P,12,FALSE()),0) -> 0 | H133: =+F133-G133 -> 0 | O133: =IFERROR(VLOOKUP("14_"&A133,SyS!$B:$P,10,FALSE()),0) -> 0 | P133: =IFERROR(VLOOKUP("14_"&A133,SyS!$B:$P,12,FALSE()),0) -> 0 | Q133: =+O133-P133 -> 0 | R133: =IFERROR(VLOOKUP("15_"&A133,SyS!$B:$P,10,FALSE()),0) -> 0 | S133: =IFERROR(VLOOKUP("15_"&A133,SyS!$B:$P,12,FALSE()),0) -> 0 | T133: =+R133-S133 -> 0 | U133: =IFERROR(VLOOKUP("16_"&A133,SyS!$B:$P,10,FALSE()),0) -> 0 | V133: =IFERROR(VLOOKUP("16_"&A133,SyS!$B:$P,12,FALSE()),0) -> 0 | W133: =+U133-V133 -> 0 | X133: =IFERROR(VLOOKUP("13_"&A133,SyS!$B:$P,10,FALSE()),0) -> 0 | Y133: =IFERROR(VLOOKUP("13_"&A133,SyS!$B:$P,12,FALSE()),0) -> 0 | Z133: =+X133-Y133 -> 0 | AA133: =IFERROR(VLOOKUP("17_"&A133,SyS!$B:$P,10,FALSE()),0) -> 0 | AB133: =IFERROR(VLOOKUP("17_"&A133,SyS!$B:$P,12,FALSE()),0) -> 0 | AC133: =+AA133-AB133 -> 0 | AG133: =IFERROR(VLOOKUP("19_"&A133,SyS!$B:$P,10,FALSE()),0) -> 0 | AH133: =IFERROR(VLOOKUP("19_"&A133,SyS!$B:$P,12,FALSE()),0) -> 0 | AI133: =+AG133-AH133 -> 0 | AM133: =IFERROR(VLOOKUP("23_"&A133,SyS!$B:$P,10,FALSE()),0) -> 0 | AN133: =IFERROR(VLOOKUP("23_"&A133,SyS!$B:$P,12,FALSE()),0) -> 0 | AO133: =+AM133-AN133 -> 0 | BK133: =IFERROR(VLOOKUP("29_"&A133,SyS!$B:$P,10,FALSE()),0) -> 0 | BL133: =IFERROR(VLOOKUP("29_"&A133,SyS!$B:$P,12,FALSE()),0) -> 0 | BM133: =+BK133-BL133 -> 0 | BN133: =IFERROR(VLOOKUP("30_"&A133,SyS!$B:$P,10,FALSE()),0) -> 0 | BO133: =IFERROR(VLOOKUP("30_"&A133,SyS!$B:$P,12,FALSE()),0) -> 0 | BP133: =+BN133-BO133 -> 0 | BQ133: =+E133+H133+K133+Q133+T133+W133+Z133+AC133+AF133+AI133+AL133+AO133+AR133+AU133+AX133+BA133+BD133+BG133+BJ133+BM133+BP133 -> 0
A134: 425140000 | B134: INTERESES RESARCITORIOS ADM. GRAL. | C134: =IFERROR(VLOOKUP("1_"&A134,SyS!$B:$P,10,FALSE()),0) -> 0 | D134: =IFERROR(VLOOKUP("1_"&A134,SyS!$B:$P,12,FALSE()),0) -> 0 | E134: =+C134-D134 -> 0 | F134: =IFERROR(VLOOKUP("2_"&A134,SyS!$B:$P,10,FALSE()),0) -> 0 | G134: =IFERROR(VLOOKUP("2_"&A134,SyS!$B:$P,12,FALSE()),0) -> 0 | H134: =+F134-G134 -> 0 | O134: =IFERROR(VLOOKUP("14_"&A134,SyS!$B:$P,10,FALSE()),0) -> 0 | P134: =IFERROR(VLOOKUP("14_"&A134,SyS!$B:$P,12,FALSE()),0) -> 0 | Q134: =+O134-P134 -> 0 | R134: =IFERROR(VLOOKUP("15_"&A134,SyS!$B:$P,10,FALSE()),0) -> 0 | S134: =IFERROR(VLOOKUP("15_"&A134,SyS!$B:$P,12,FALSE()),0) -> 0 | T134: =+R134-S134 -> 0 | U134: =IFERROR(VLOOKUP("16_"&A134,SyS!$B:$P,10,FALSE()),0) -> 0 | V134: =IFERROR(VLOOKUP("16_"&A134,SyS!$B:$P,12,FALSE()),0) -> 0 | W134: =+U134-V134 -> 0 | X134: =IFERROR(VLOOKUP("13_"&A134,SyS!$B:$P,10,FALSE()),0) -> 0 | Y134: =IFERROR(VLOOKUP("13_"&A134,SyS!$B:$P,12,FALSE()),0) -> 0 | Z134: =+X134-Y134 -> 0 | AA134: =IFERROR(VLOOKUP("17_"&A134,SyS!$B:$P,10,FALSE()),0) -> 0 | AB134: =IFERROR(VLOOKUP("17_"&A134,SyS!$B:$P,12,FALSE()),0) -> 0 | AC134: =+AA134-AB134 -> 0 | AG134: =IFERROR(VLOOKUP("19_"&A134,SyS!$B:$P,10,FALSE()),0) -> 0 | AH134: =IFERROR(VLOOKUP("19_"&A134,SyS!$B:$P,12,FALSE()),0) -> 0 | AI134: =+AG134-AH134 -> 0 | AM134: =IFERROR(VLOOKUP("23_"&A134,SyS!$B:$P,10,FALSE()),0) -> 0 | AN134: =IFERROR(VLOOKUP("23_"&A134,SyS!$B:$P,12,FALSE()),0) -> 0 | AO134: =+AM134-AN134 -> 0 | BK134: =IFERROR(VLOOKUP("29_"&A134,SyS!$B:$P,10,FALSE()),0) -> 0 | BL134: =IFERROR(VLOOKUP("29_"&A134,SyS!$B:$P,12,FALSE()),0) -> 0 | BM134: =+BK134-BL134 -> 0 | BN134: =IFERROR(VLOOKUP("30_"&A134,SyS!$B:$P,10,FALSE()),0) -> 0 | BO134: =IFERROR(VLOOKUP("30_"&A134,SyS!$B:$P,12,FALSE()),0) -> 0 | BP134: =+BN134-BO134 -> 0 | BQ134: =+E134+H134+K134+Q134+T134+W134+Z134+AC134+AF134+AI134+AL134+AO134+AR134+AU134+AX134+BA134+BD134+BG134+BJ134+BM134+BP134 -> 0
A135: 425150000 | B135: ALQUILER INMUEBLE ADM. GRAL. | C135: =IFERROR(VLOOKUP("1_"&A135,SyS!$B:$P,10,FALSE()),0) -> 0 | D135: =IFERROR(VLOOKUP("1_"&A135,SyS!$B:$P,12,FALSE()),0) -> 0 | E135: =+C135-D135 -> 0 | F135: =IFERROR(VLOOKUP("2_"&A135,SyS!$B:$P,10,FALSE()),0) -> 1181.74 | G135: =IFERROR(VLOOKUP("2_"&A135,SyS!$B:$P,12,FALSE()),0) -> 0 | H135: =+F135-G135 -> 1181.74 | O135: =IFERROR(VLOOKUP("14_"&A135,SyS!$B:$P,10,FALSE()),0) -> 0 | P135: =IFERROR(VLOOKUP("14_"&A135,SyS!$B:$P,12,FALSE()),0) -> 0 | Q135: =+O135-P135 -> 0 | R135: =IFERROR(VLOOKUP("15_"&A135,SyS!$B:$P,10,FALSE()),0) -> 1235.4 | S135: =IFERROR(VLOOKUP("15_"&A135,SyS!$B:$P,12,FALSE()),0) -> 0 | T135: =+R135-S135 -> 1235.4 | U135: =IFERROR(VLOOKUP("16_"&A135,SyS!$B:$P,10,FALSE()),0) -> 0 | V135: =IFERROR(VLOOKUP("16_"&A135,SyS!$B:$P,12,FALSE()),0) -> 0 | W135: =+U135-V135 -> 0 | X135: =IFERROR(VLOOKUP("13_"&A135,SyS!$B:$P,10,FALSE()),0) -> 0 | Y135: =IFERROR(VLOOKUP("13_"&A135,SyS!$B:$P,12,FALSE()),0) -> 0 | Z135: =+X135-Y135 -> 0 | AA135: =IFERROR(VLOOKUP("17_"&A135,SyS!$B:$P,10,FALSE()),0) -> 0 | AB135: =IFERROR(VLOOKUP("17_"&A135,SyS!$B:$P,12,FALSE()),0) -> 0 | AC135: =+AA135-AB135 -> 0 | AG135: =IFERROR(VLOOKUP("19_"&A135,SyS!$B:$P,10,FALSE()),0) -> 0 | AH135: =IFERROR(VLOOKUP("19_"&A135,SyS!$B:$P,12,FALSE()),0) -> 0 | AI135: =+AG135-AH135 -> 0 | AM135: =IFERROR(VLOOKUP("23_"&A135,SyS!$B:$P,10,FALSE()),0) -> 0 | AN135: =IFERROR(VLOOKUP("23_"&A135,SyS!$B:$P,12,FALSE()),0) -> 0 | AO135: =+AM135-AN135 -> 0 | BK135: =IFERROR(VLOOKUP("29_"&A135,SyS!$B:$P,10,FALSE()),0) -> 0 | BL135: =IFERROR(VLOOKUP("29_"&A135,SyS!$B:$P,12,FALSE()),0) -> 0 | BM135: =+BK135-BL135 -> 0 | BN135: =IFERROR(VLOOKUP("30_"&A135,SyS!$B:$P,10,FALSE()),0) -> 0 | BO135: =IFERROR(VLOOKUP("30_"&A135,SyS!$B:$P,12,FALSE()),0) -> 0 | BP135: =+BN135-BO135 -> 0 | BQ135: =+E135+H135+K135+Q135+T135+W135+Z135+AC135+AF135+AI135+AL135+AO135+AR135+AU135+AX135+BA135+BD135+BG135+BJ135+BM135+BP135 -> 2417.14
A136: 425160000 | B136: CUOTA SOCIETARIA MINERA ADM. GRAL. | C136: =IFERROR(VLOOKUP("1_"&A136,SyS!$B:$P,10,FALSE()),0) -> 0 | D136: =IFERROR(VLOOKUP("1_"&A136,SyS!$B:$P,12,FALSE()),0) -> 0 | E136: =+C136-D136 -> 0 | F136: =IFERROR(VLOOKUP("2_"&A136,SyS!$B:$P,10,FALSE()),0) -> 0 | G136: =IFERROR(VLOOKUP("2_"&A136,SyS!$B:$P,12,FALSE()),0) -> 0 | H136: =+F136-G136 -> 0 | O136: =IFERROR(VLOOKUP("14_"&A136,SyS!$B:$P,10,FALSE()),0) -> 0 | P136: =IFERROR(VLOOKUP("14_"&A136,SyS!$B:$P,12,FALSE()),0) -> 0 | Q136: =+O136-P136 -> 0 | R136: =IFERROR(VLOOKUP("15_"&A136,SyS!$B:$P,10,FALSE()),0) -> 0 | S136: =IFERROR(VLOOKUP("15_"&A136,SyS!$B:$P,12,FALSE()),0) -> 0 | T136: =+R136-S136 -> 0 | U136: =IFERROR(VLOOKUP("16_"&A136,SyS!$B:$P,10,FALSE()),0) -> 0 | V136: =IFERROR(VLOOKUP("16_"&A136,SyS!$B:$P,12,FALSE()),0) -> 0 | W136: =+U136-V136 -> 0 | X136: =IFERROR(VLOOKUP("13_"&A136,SyS!$B:$P,10,FALSE()),0) -> 0 | Y136: =IFERROR(VLOOKUP("13_"&A136,SyS!$B:$P,12,FALSE()),0) -> 0 | Z136: =+X136-Y136 -> 0 | AA136: =IFERROR(VLOOKUP("17_"&A136,SyS!$B:$P,10,FALSE()),0) -> 0 | AB136: =IFERROR(VLOOKUP("17_"&A136,SyS!$B:$P,12,FALSE()),0) -> 0 | AC136: =+AA136-AB136 -> 0 | AG136: =IFERROR(VLOOKUP("19_"&A136,SyS!$B:$P,10,FALSE()),0) -> 0 | AH136: =IFERROR(VLOOKUP("19_"&A136,SyS!$B:$P,12,FALSE()),0) -> 0 | AI136: =+AG136-AH136 -> 0 | AM136: =IFERROR(VLOOKUP("23_"&A136,SyS!$B:$P,10,FALSE()),0) -> 0 | AN136: =IFERROR(VLOOKUP("23_"&A136,SyS!$B:$P,12,FALSE()),0) -> 0 | AO136: =+AM136-AN136 -> 0 | BK136: =IFERROR(VLOOKUP("29_"&A136,SyS!$B:$P,10,FALSE()),0) -> 0 | BL136: =IFERROR(VLOOKUP("29_"&A136,SyS!$B:$P,12,FALSE()),0) -> 0 | BM136: =+BK136-BL136 -> 0 | BN136: =IFERROR(VLOOKUP("30_"&A136,SyS!$B:$P,10,FALSE()),0) -> 0 | BO136: =IFERROR(VLOOKUP("30_"&A136,SyS!$B:$P,12,FALSE()),0) -> 0 | BP136: =+BN136-BO136 -> 0 | BQ136: =+E136+H136+K136+Q136+T136+W136+Z136+AC136+AF136+AI136+AL136+AO136+AR136+AU136+AX136+BA136+BD136+BG136+BJ136+BM136+BP136 -> 0
A137: 425170000 | B137: MENSAJERIA ADM. GRAL. | C137: =IFERROR(VLOOKUP("1_"&A137,SyS!$B:$P,10,FALSE()),0) -> 0 | D137: =IFERROR(VLOOKUP("1_"&A137,SyS!$B:$P,12,FALSE()),0) -> 0 | E137: =+C137-D137 -> 0 | F137: =IFERROR(VLOOKUP("2_"&A137,SyS!$B:$P,10,FALSE()),0) -> 0 | G137: =IFERROR(VLOOKUP("2_"&A137,SyS!$B:$P,12,FALSE()),0) -> 0 | H137: =+F137-G137 -> 0 | O137: =IFERROR(VLOOKUP("14_"&A137,SyS!$B:$P,10,FALSE()),0) -> 0 | P137: =IFERROR(VLOOKUP("14_"&A137,SyS!$B:$P,12,FALSE()),0) -> 0 | Q137: =+O137-P137 -> 0 | R137: =IFERROR(VLOOKUP("15_"&A137,SyS!$B:$P,10,FALSE()),0) -> 0 | S137: =IFERROR(VLOOKUP("15_"&A137,SyS!$B:$P,12,FALSE()),0) -> 0 | T137: =+R137-S137 -> 0 | U137: =IFERROR(VLOOKUP("16_"&A137,SyS!$B:$P,10,FALSE()),0) -> 0 | V137: =IFERROR(VLOOKUP("16_"&A137,SyS!$B:$P,12,FALSE()),0) -> 0 | W137: =+U137-V137 -> 0 | X137: =IFERROR(VLOOKUP("13_"&A137,SyS!$B:$P,10,FALSE()),0) -> 0 | Y137: =IFERROR(VLOOKUP("13_"&A137,SyS!$B:$P,12,FALSE()),0) -> 0 | Z137: =+X137-Y137 -> 0 | AA137: =IFERROR(VLOOKUP("17_"&A137,SyS!$B:$P,10,FALSE()),0) -> 0 | AB137: =IFERROR(VLOOKUP("17_"&A137,SyS!$B:$P,12,FALSE()),0) -> 0 | AC137: =+AA137-AB137 -> 0 | AG137: =IFERROR(VLOOKUP("19_"&A137,SyS!$B:$P,10,FALSE()),0) -> 0 | AH137: =IFERROR(VLOOKUP("19_"&A137,SyS!$B:$P,12,FALSE()),0) -> 0 | AI137: =+AG137-AH137 -> 0 | AM137: =IFERROR(VLOOKUP("23_"&A137,SyS!$B:$P,10,FALSE()),0) -> 0 | AN137: =IFERROR(VLOOKUP("23_"&A137,SyS!$B:$P,12,FALSE()),0) -> 0 | AO137: =+AM137-AN137 -> 0 | BK137: =IFERROR(VLOOKUP("29_"&A137,SyS!$B:$P,10,FALSE()),0) -> 0 | BL137: =IFERROR(VLOOKUP("29_"&A137,SyS!$B:$P,12,FALSE()),0) -> 0 | BM137: =+BK137-BL137 -> 0 | BN137: =IFERROR(VLOOKUP("30_"&A137,SyS!$B:$P,10,FALSE()),0) -> 0 | BO137: =IFERROR(VLOOKUP("30_"&A137,SyS!$B:$P,12,FALSE()),0) -> 0 | BP137: =+BN137-BO137 -> 0 | BQ137: =+E137+H137+K137+Q137+T137+W137+Z137+AC137+AF137+AI137+AL137+AO137+AR137+AU137+AX137+BA137+BD137+BG137+BJ137+BM137+BP137 -> 0
A138: 425180000 | B138: COMUNICACIONES ADM. GRAL. | C138: =IFERROR(VLOOKUP("1_"&A138,SyS!$B:$P,10,FALSE()),0) -> 0 | D138: =IFERROR(VLOOKUP("1_"&A138,SyS!$B:$P,12,FALSE()),0) -> 0 | E138: =+C138-D138 -> 0 | F138: =IFERROR(VLOOKUP("2_"&A138,SyS!$B:$P,10,FALSE()),0) -> 0 | G138: =IFERROR(VLOOKUP("2_"&A138,SyS!$B:$P,12,FALSE()),0) -> 0 | H138: =+F138-G138 -> 0 | O138: =IFERROR(VLOOKUP("14_"&A138,SyS!$B:$P,10,FALSE()),0) -> 0 | P138: =IFERROR(VLOOKUP("14_"&A138,SyS!$B:$P,12,FALSE()),0) -> 0 | Q138: =+O138-P138 -> 0 | R138: =IFERROR(VLOOKUP("15_"&A138,SyS!$B:$P,10,FALSE()),0) -> 0 | S138: =IFERROR(VLOOKUP("15_"&A138,SyS!$B:$P,12,FALSE()),0) -> 0 | T138: =+R138-S138 -> 0 | U138: =IFERROR(VLOOKUP("16_"&A138,SyS!$B:$P,10,FALSE()),0) -> 0 | V138: =IFERROR(VLOOKUP("16_"&A138,SyS!$B:$P,12,FALSE()),0) -> 0 | W138: =+U138-V138 -> 0 | X138: =IFERROR(VLOOKUP("13_"&A138,SyS!$B:$P,10,FALSE()),0) -> 0 | Y138: =IFERROR(VLOOKUP("13_"&A138,SyS!$B:$P,12,FALSE()),0) -> 0 | Z138: =+X138-Y138 -> 0 | AA138: =IFERROR(VLOOKUP("17_"&A138,SyS!$B:$P,10,FALSE()),0) -> 0 | AB138: =IFERROR(VLOOKUP("17_"&A138,SyS!$B:$P,12,FALSE()),0) -> 0 | AC138: =+AA138-AB138 -> 0 | AG138: =IFERROR(VLOOKUP("19_"&A138,SyS!$B:$P,10,FALSE()),0) -> 0 | AH138: =IFERROR(VLOOKUP("19_"&A138,SyS!$B:$P,12,FALSE()),0) -> 0 | AI138: =+AG138-AH138 -> 0 | AM138: =IFERROR(VLOOKUP("23_"&A138,SyS!$B:$P,10,FALSE()),0) -> 0 | AN138: =IFERROR(VLOOKUP("23_"&A138,SyS!$B:$P,12,FALSE()),0) -> 0 | AO138: =+AM138-AN138 -> 0 | BK138: =IFERROR(VLOOKUP("29_"&A138,SyS!$B:$P,10,FALSE()),0) -> 0 | BL138: =IFERROR(VLOOKUP("29_"&A138,SyS!$B:$P,12,FALSE()),0) -> 0 | BM138: =+BK138-BL138 -> 0 | BN138: =IFERROR(VLOOKUP("30_"&A138,SyS!$B:$P,10,FALSE()),0) -> 0 | BO138: =IFERROR(VLOOKUP("30_"&A138,SyS!$B:$P,12,FALSE()),0) -> 0 | BP138: =+BN138-BO138 -> 0 | BQ138: =+E138+H138+K138+Q138+T138+W138+Z138+AC138+AF138+AI138+AL138+AO138+AR138+AU138+AX138+BA138+BD138+BG138+BJ138+BM138+BP138 -> 0
A139: 433050000 | B139: Comunicaciones Adm. Gral USD | C139: =IFERROR(VLOOKUP("1_"&A139,SyS!$B:$P,10,FALSE()),0) -> 0 | D139: =IFERROR(VLOOKUP("1_"&A139,SyS!$B:$P,12,FALSE()),0) -> 0 | E139: =+C139-D139 -> 0 | F139: =IFERROR(VLOOKUP("2_"&A139,SyS!$B:$P,10,FALSE()),0) -> 0 | G139: =IFERROR(VLOOKUP("2_"&A139,SyS!$B:$P,12,FALSE()),0) -> 0 | H139: =+F139-G139 -> 0 | O139: =IFERROR(VLOOKUP("14_"&A139,SyS!$B:$P,10,FALSE()),0) -> 0 | P139: =IFERROR(VLOOKUP("14_"&A139,SyS!$B:$P,12,FALSE()),0) -> 0 | Q139: =+O139-P139 -> 0 | R139: =IFERROR(VLOOKUP("15_"&A139,SyS!$B:$P,10,FALSE()),0) -> 0 | S139: =IFERROR(VLOOKUP("15_"&A139,SyS!$B:$P,12,FALSE()),0) -> 0 | T139: =+R139-S139 -> 0 | U139: =IFERROR(VLOOKUP("16_"&A139,SyS!$B:$P,10,FALSE()),0) -> 0 | V139: =IFERROR(VLOOKUP("16_"&A139,SyS!$B:$P,12,FALSE()),0) -> 0 | W139: =+U139-V139 -> 0 | X139: =IFERROR(VLOOKUP("13_"&A139,SyS!$B:$P,10,FALSE()),0) -> 0 | Y139: =IFERROR(VLOOKUP("13_"&A139,SyS!$B:$P,12,FALSE()),0) -> 0 | Z139: =+X139-Y139 -> 0 | AA139: =IFERROR(VLOOKUP("17_"&A139,SyS!$B:$P,10,FALSE()),0) -> 0 | AB139: =IFERROR(VLOOKUP("17_"&A139,SyS!$B:$P,12,FALSE()),0) -> 0 | AC139: =+AA139-AB139 -> 0 | AG139: =IFERROR(VLOOKUP("19_"&A139,SyS!$B:$P,10,FALSE()),0) -> 0 | AH139: =IFERROR(VLOOKUP("19_"&A139,SyS!$B:$P,12,FALSE()),0) -> 0 | AI139: =+AG139-AH139 -> 0 | AM139: =IFERROR(VLOOKUP("23_"&A139,SyS!$B:$P,10,FALSE()),0) -> 0 | AN139: =IFERROR(VLOOKUP("23_"&A139,SyS!$B:$P,12,FALSE()),0) -> 0 | AO139: =+AM139-AN139 -> 0 | BK139: =IFERROR(VLOOKUP("29_"&A139,SyS!$B:$P,10,FALSE()),0) -> 0 | BL139: =IFERROR(VLOOKUP("29_"&A139,SyS!$B:$P,12,FALSE()),0) -> 0 | BM139: =+BK139-BL139 -> 0 | BN139: =IFERROR(VLOOKUP("30_"&A139,SyS!$B:$P,10,FALSE()),0) -> 0 | BO139: =IFERROR(VLOOKUP("30_"&A139,SyS!$B:$P,12,FALSE()),0) -> 0 | BP139: =+BN139-BO139 -> 0 | BQ139: =+E139+H139+K139+Q139+T139+W139+Z139+AC139+AF139+AI139+AL139+AO139+AR139+AU139+AX139+BA139+BD139+BG139+BJ139+BM139+BP139 -> 0
