Workbook

Sheet Balance
A1: ESTADO DE SITUACION PATRIMONIAL
A2: Al 31 de julio de 2026 - Cifras expresadas en dólares
F5: 46234 | G5: 31.03.04 | L5: =+F5 -> 46203
B6: ACTIVO: | G6: Historico | I6: PASIVO
C7: ACTIVO CORRIENTE | I7: PASIVO CORRIENTE
D8: Caja y Bancos (Nota 4.a) | F8: =+'Activo y Pasivo'!F17 -> 13953.93 | J8: Deudas Comerciales (Nota 4.e) | L8: =+'Activo y Pasivo'!F68 -> 71988.875
D9: Otros Créditos (Nota 4.b) | F9: =+'Activo y Pasivo'!F48 -> 3716769.9 | J9: Cargas Fiscales (Nota 4.f) | L9: =+'Activo y Pasivo'!F81 -> 1368944.1
D10: Otros Activos (Nota 4.c) | F10: =+'Activo y Pasivo'!F52 -> 104684 | J10: Remuneraciones y Cargas Sociales (Nota 4.g) | L10: =+'Activo y Pasivo'!F88 -> 58289.6
C11: Total del Activo corriente | F11: =SUM(F8:F10) -> 3835407.9 | I11: Total del Pasivo Corriente | L11: =SUM(L8:L10) -> 1499222.6
I12: Total del Pasivo | L12: =+L11 -> 1499222.6
D14: Inversiones (Nota 4.d) | F14: =+'Activo y Pasivo'!F58 -> 0
D15: Bienes de Uso (Anexo I) | F15: =+'Anexo I'!K24 -> 72868.68
I16: PATRIMONIO NETO (Según estado respectivo) | L16: =+Pat.Neto!J21 -> 2409053.9
C18: Total del Activo no corriente | F18: =SUM(F14:F17) -> 72868.68
C20: Total del Activo | F20: =+F11+F18 -> 3908276.5 | I20: Total del Pasivo y Patrimonio Neto | L20: =+L12+L16 -> 3908276.5
A22: Las notas y anexos adjuntos forman parte integrante de los estados contables
A23: Informe profesional por separado | L23: =+L20-F20 -> 0.0029113134
D31: Miguel Ángel Alonso | F31: Pedro Nicholson | K31: Alejandro Poletto
D32: Contador Público (U.C.A.) | F32: Síndico | K32: Southern Copper Arg. S.R.L.
D33: C.P.C.E.C.A.B.A. Tº176 Fº03 | K33: Gerente

Sheet Resultados
A1: ESTADO DE RESULTADOS
A2: =+Balance!A2 -> Al 30 de junio de 2026 - Cifras expresadas en dólares
B5: =+Balance!F5 -> 46203 | C5: =+Balance!F5 -> 46203
A8: Ventas y servicios netas | C8: 0
A9: Costo de mercaderías vendidas | C9: 0
A10: Ganancia neta | C10: =+C8-C9 -> 0
A12: Gastos de comercialización (Anexo II) | C12: =+'Anexo II'!G102 -> 0
A13: Gastos de administración (Anexo II) | C13: =-'Anexo II'!F102 -> -530007.27
A14: Gastos de financieros (Anexo II) | C14: =+'Anexo II'!I102 -> 0
A15: Gastos de Exploración | C15: =-'Anexo II'!H102 -> -616736.47
A16: Otros ingresos y egresos | C16: 0
A17: Resultados financieros y por tenencia | C17: =-'Distribución por línea'!C149-'Distribución por línea'!C109 -> -46243.868
A18: Otros ingresos y egresos | C18: =-'Distribución por línea'!C112
A19: Resultados Extraordinarios | C19: =-'Distribución por línea'!C208
A21: Pérdida antes de impuesto a las Ganancias | C21: =+C10+SUM(C12:C20) -> -1192987.6
A23: Impuesto a las Ganancias | C23: 0
A25: Pérdida del ejercicio | C25: =+C21-C23 -> -1192987.6
A30: Las notas y anexos adjuntos forman parte integrante de los estados contables
A31: Informe profesional por separado
A38: =+Balance!D31 -> Miguel Ángel Alonso | C38: =+Balance!F31 -> Pedro Nicholson | E38: =+Balance!K31 -> Alejandro Poletto
A39: =+Balance!D32 -> Contador Público (U.C.A.) | C39: =+Balance!F32 -> Síndico | E39: =+Balance!K32 -> Southern Copper Arg. S.R.L.
A40: =+Balance!D33 -> C.P.C.E.C.A.B.A. Tº176 Fº03 | E40: =+Balance!K33 -> Gerente

Sheet Pat.Neto
A1: ESTADO DE EVOLUCION DEL PATRIMONIO NETO
B2: =+Balance!A2 -> Al 30 de junio de 2026 - Cifras expresadas en dólares
J5: =+Balance!F5 -> 46203
B6: CONCEPTO | C6: Aportes de los propietarios | F6: Ganancias | G6: Reservadas | I6: Resultados | J6: Total del
C7: Capital | D7: Cuotas Pendientes de integracion | E7: Capital | F7: Reserva | G7: Otras | H7: Aportes | I7: no | J7: patrimonio
C8: integrado | E8: suscripto | F8: legal | G8: reservas | H8: Irrevocables | I8: asignados | J8: neto
C10: USD | D10: USD | E10: USD | F10: USD | G10: USD | I10: USD | J10: USD
B12: Saldos al inicio del ejercicio | C12: 51718583 | D12: 0 | E12: 51718583 | F12: 0 | G12: 0 | H12: 0 | I12: -48116541 | J12: =+E12+I12 -> 3497357.5
B13: A.R.E.A. | I13: 0 | J13: =+I13 -> 0
B14: Diferencia Resultados no Asignados | I14: 0 | J14: =+I14 -> 0
C15: =SUM(C12:C12) -> 51613899 | D15: =SUM(D12:D12) -> 0 | E15: =SUM(E12:E12) -> 51613899 | F15: =SUM(F12:F12) -> 0 | G15: =SUM(G12:G12) -> 0 | H15: =SUM(H12:H12) -> 0 | I15: =SUM(I12:I14) -> -48116541 | J15: =+J12+J13+J14 -> 3497357.5
B17: Aumento de capital al 31/07/2026 | C17: 176680 | E17: =+C17 | J17: =+E17
B19: Ganancia (Pérdida) del ejercicio | I19: =+Resultados!C25 -> -1192987.6 | J19: =+I19 -> -1192987.6
B21: Saldos al 31.7.2026 | C21: =+C15+C17 -> 51718583 | D21: =SUM(D15:D19) -> 0 | E21: =SUM(E15:E17) -> 51718583 | F21: =+F15 -> 0 | G21: =+G15 -> 0 | H21: =+H15 -> 0 | I21: =SUM(I15:I19) -> -49309529 | J21: =SUM(J15:J19) -> 2409053.9
B23: Las notas y anexos adjuntos forman parte integrante de los estados contables
B24: Informe profesional por separado
C31: =+Balance!D31 -> Miguel Ángel Alonso | F31: =+Balance!F31 -> Pedro Nicholson | I31: =+Balance!K31 -> Alejandro Poletto
C32: =+Balance!D32 -> Contador Público (U.C.A.) | F32: =+Balance!F32 -> Síndico | I32: =+Balance!K32 -> Southern Copper Arg. S.R.L.
C33: =+Balance!D33 -> C.P.C.E.C.A.B.A. Tº176 Fº03 | I33: =+Balance!K33 -> Gerente

Sheet Activo y Pasivo
B1: NOTA 4: | D1: COMPOSICION DE LOS RUBROS
B2: =+Balance!A2 -> Al 30 de junio de 2026 - Cifras expresadas en dólares
F4: =+Balance!F5 -> 46203
B5: ACTIVO
B6: Activo Corriente
B7: a. | C7: Caja y Bancos
D8: - Caja | F8: =+'Distribución por línea'!C3
D9: - Banco de Crédito - BCP | F9: =+'Distribución por línea'!C4 -> 5746.23
D10: - ICBC c/c | F10: =+'Distribución por línea'!C5 -> 7239.24
D11: - Banco Macro USD | F11: =+'Distribución por línea'!C7 -> 981.5
D12: - Banco Macro Pesos | F12: =+'Distribución por línea'!C6 -> -15.71
D13: - Banco Macro Pesos Cta Especial | F13: =+'Distribución por línea'!C8
D14: - Banco Galicia c/c | F14: =+'Distribución por línea'!C9 -> 2.67
D15: - Fondo fima premiun | F15: =+'Distribución por línea'!C10
D16: - Tarjetas VISA | F16: =+'Distribución por línea'!C11
F17: =SUM(F8:F16) -> 13953.93
B19: b. | C19: Otros Créditos
D20: - Zento S.A. | F20: =+'Distribución por línea'!C30
D21: - Iva crédito fiscal | F21: =+'Distribución por línea'!C12
D22: - Iva saldo a favor | F22: =+'Distribución por línea'!C13 -> 1132355.3
D23: - IIBB saldo a favor | F23: =+'Distribución por línea'!C16 -> 5340.7
D24: - Retenciones y percepciones iva | F24: =+'Distribución por línea'!C14 -> -1.7763568e-15
D25: - Retenciones y percepciones IIBB | F25: =+'Distribución por línea'!C15 -> -8.8817842e-16
D26: - Crédito Imp. L.25413 | F26: =+'Distribución por línea'!C17 -> 35314.56
D27: - Imp. Gcia Mínima Presunta | F27: =+'Distribución por línea'!C18 -> 358.96
D28: - Anticipo Imp. Gcia. Mínima Presunta | F28: =+'Distribución por línea'!C23
D29: - Percepción RG 4815 35% computable | F29: =+'Distribución por línea'!C24 -> 17670.09
D30: - Iva importación de servicios | F30: =+'Distribución por línea'!C25
D31: - Southern Cooper Corporation Cta Part | F31: =+'Distribución por línea'!C26 -> 65129.21
D32: - Cía. Minera Los Tolmos S.A. Cta. Part. | F32: =+'Distribución por línea'!C27 -> 0.62
D33: - Depósito en garantía alquiler | F33: =+'Distribución por línea'!C38 -> 73.46
D34: - Garantia a Cobrar/Recuperar | F34: =+'Distribución por línea'!C36
D35: - Adelanto Wilfredo Loza | F35: =+'Distribución por línea'!C31
D36: - Adelantos de Sueldos | F36: =+'Distribución por línea'!C32
D37: - Anticipos a proveedores | F37: =+'Distribución por línea'!D61+'Distribución por línea'!C35 -> 219.28
D38: - Anticipo Geologos | F38: =+'Distribución por línea'!C33
D39: - Anticipo de Fondos | F39: =+'Distribución por línea'!C34 -> 11810.75
D40: - Seguros a devengar | F40: =+'Distribución por línea'!C28 -> 4529.05
D41: - Cuentas por cobrar a Personal | F41: =+'Distribución por línea'!C29
D42: - Ret/Perc. Ganancias | F42: =+'Distribución por línea'!C19
...

Sheet Anexo I
K1: ANEXO I
A4: BIENES DE USO
A5: Correspondiente al ejercicio económico finalizado el 31 de julio de 2026
B8: VALOR DE ORIGEN | F8: DEPRECIACIONES
B9: VALORES AL | E9: VALORES AL | F9: ACUMULADAS | H9: DEL EJERCICIO | J9: ACUMULADAS | K9: NETO
A10: CONCEPTO | B10: COMIENZO DEL | C10: AUMENTOS | D10: DISMINUCIONES | E10: CIERRE DEL | F10: AL INICIO DEL | G10: BAJAS | H10: ALICUOTA | I10: MONTO | J10: AL CIERRE DEL | K10: RESULTANTE
B11: EJERCICIO | E11: EJERCICIO | F11: EJERCICIO | I11: MENSUAL | J11: EJERCICIO | K11: AL 31.07.2026
B12: USD | C12: USD | D12: USD | E12: USD | F12: USD | G12: USD | I12: USD | J12: USD | K12: USD
A15: - Muebles y Utiles | B15: 130976.14 | C15: 0 | D15: 0 | E15: =SUM(B15:D15) -> 130976.14 | F15: 109789.38 | G15: 0 | H15: =10/100 -> 0.1 | I15: =+J15-F15 -> 973.22 | J15: =-'Distribución por línea'!C45 -> 110762.6 | K15: =+E15-J15 -> 20213.54
A16: - Equipamiento Exploración | B16: 127410.39 | C16: 9409.86 | D16: 0 | E16: =SUM(B16:D16) -> 136820.25 | F16: 124747.23 | G16: 0 | H16: =33.3333333333333/100 -> 0.33333333 | I16: =+J16-F16 -> 2368.67 | J16: =-'Distribución por línea'!C53 -> 127115.9 | K16: =+E16-J16 -> 9704.35
A17: - Equipos | B17: 58450.05 | C17: 0 | D17: 0 | E17: =SUM(B17:D17) -> 58450.05 | F17: 55436.52 | G17: 0 | H17: =20/100 -> 0.2 | I17: =+J17-F17 -> 206.07 | J17: =-'Distribución por línea'!C46 -> 55642.59 | K17: =+E17-J17 -> 2807.46
A18: - Herramientas | B18: 33289.65 | C18: 0 | D18: 0 | E18: =SUM(B18:D18) -> 33289.65 | F18: 23082.15 | G18: 0 | H18: 0.1 | I18: =+J18-F18 -> 406.97 | J18: =-'Distribución por línea'!C47 -> 23489.12 | K18: =+E18-J18 -> 9800.53
A19: - Equipos de Computación | B19: 76103.66 | C19: 2268.65 | D19: 0 | E19: =SUM(B19:D19) -> 78372.31 | F19: 65705.95 | G19: 0 | H19: 0.2 | I19: =+J19-F19 -> 1758.74 | J19: =-'Distribución por línea'!C49 -> 67464.69 | K19: =+E19-J19 -> 10907.62
A20: - Software | B20: 133453.72 | C20: 0 | D20: 0 | E20: =SUM(B20:D20) -> 133453.72 | F20: 133453.72 | G20: 0 | H20: 0.2 | I20: =+J20-F20 -> 0 | J20: 133453.72 | K20: =+E20-J20 -> 0
A21: - Rodados | B21: 279626.68 | C21: 0 | D21: 0 | E21: =SUM(B21:D21) -> 279626.68 | F21: 259749.99 | G21: 0 | H21: =20/100 -> 0.2 | I21: =+J21-F21 -> 6369.75 | J21: =-'Distribución por línea'!C51 -> 266119.74 | K21: =+E21-J21 -> 13506.94
A22: - Instalaciones | B22: 11629.81 | C22: 0 | D22: 0 | E22: =SUM(B22:D22) -> 11629.81 | F22: 5406.12 | G22: 0 | H22: 0.1 | I22: =+J22-F22 -> 295.45 | J22: =-'Distribución por línea'!C55 -> 5701.57 | K22: =+E22-J22 -> 5928.24
A24: =+Pat.Neto!B21 -> Saldos al 30.6.2026 | B24: =SUM(B15:B23) -> 850940.1 | C24: =SUM(C15:C23) -> 11678.51 | D24: =SUM(D15:D23) -> 0 | E24: =SUM(E15:E23) -> 862618.61 | F24: =SUM(F15:F23) -> 777371.06 | G24: =SUM(G15:G23) -> 0 | I24: =SUM(I15:I22) -> 12378.87 | J24: =SUM(J15:J23) -> 789749.93 | K24: =SUM(K15:K23) -> 72868.68
A26: Las notas y anexos adjuntos forman parte integrante de los estados contables
A27: Informe profesional por separado
B33: =+Balance!D31 -> Miguel Ángel Alonso | F33: =+Balance!F31 -> Pedro Nicholson | J33: =+Balance!K31 -> Alejandro Poletto
B34: =+Balance!D32 -> Contador Público (U.C.A.) | F34: =+Balance!F32 -> Síndico | J34: =+Balance!K32 -> Southern Copper Arg. S.R.L.
B35: =+Balance!D33 -> C.P.C.E.C.A.B.A. Tº176 Fº03 | J35: =+Balance!K33 -> Gerente

Sheet Anexo II
J1: ANEXO II
A3: Información Requerida por el Art. 64 Inc. b) de la Ley 19.550 | I3: Anexo II
A4: =+Balance!A2 -> Al 30 de junio de 2026 - Cifras expresadas en dólares
E6: TOTALES | F6: GASTOS | G6: GASTOS | H6: GASTOS | I6: GASTOS | J6: TOTALES
B7: CONCEPTOS | E7: AL | F7: DE | G7: DE | H7: DE | J7: AL
E8: =+Balance!F5 -> 46203 | F8: ADMINISTRACION | G8: COMERCIALIZACION | H8: EXPLORACION | I8: FINANCIEROS | J8: 31.03.02
A10: - | B10: ALOJAMIENTO | E10: =SUM(F10:I10) -> 36709.74 | H10: =+'Distribución por línea'!C164 -> 36709.74
A11: - | B11: ALQUILERES (Inmuebles) | E11: =SUM(F11:I11) -> 185113.95 | F11: =+'Distribución por línea'!C175+'Distribución por línea'!C205 -> 185113.95
A12: - | B12: ANALISIS MUESTRAS | E12: =SUM(F12:I12) -> 41896.28 | H12: =+'Distribución por línea'!C176 -> 41896.28
A13: - | B13: ALQUILERES VARIOS | E13: =SUM(F13:I13) -> 0 | H13: =+'Distribución por línea'!C144
A14: - | B14: ALQUILER DE VEHÍCULOS | E14: =SUM(F14:I14) -> 130.73 | H14: =+'Distribución por línea'!C156 -> 130.73
A15: - | B15: ALQUILER DE MAQUINARIA | E15: =SUM(F15:I15) -> 0 | H15: =+'Distribución por línea'!C186
A16: - | B16: ALQUILERES EQ. DE CAMPO | E16: =SUM(F16:I16) -> 21.03 | H16: =+'Distribución por línea'!C123+'Distribución por línea'!C120 -> 21.03
A17: - | B17: ACUERDO DE INVERSIONES | E17: =SUM(F17:I17) -> 0 | H17: =+'Distribución por línea'!C160
A18: - | B18: ADQUISICIÓN INFORMACIÓN GEOLÓGICA | E18: =SUM(F18:I18) -> 0 | H18: =+'Distribución por línea'!C170
A19: - | B19: ADQUISICIÓN INFORMACIÓN GEOFÍSICA | E19: =SUM(F19:I19) -> 0 | H19: =+'Distribución por línea'!C171+'Distribución por línea'!C172
A20: - | B20: DEPRECIACIONES | E20: =SUM(F20:I20) -> 12378.87 | F20: =+'Anexo I'!I24 -> 12378.87
A21: - | B21: CARGAS SOCIALES | E21: =SUM(F21:I21) -> 46687.64 | F21: =+'Distribución por línea'!C117 -> 10000.93 | H21: =+'Distribución por línea'!C192 -> 36686.71
A22: - | B22: CANON | E22: =SUM(F22:I22) -> 34732.29 | H22: =+'Distribución por línea'!C157+'Distribución por línea'!C222+'Distribución por línea'!C223+'Distribución por línea'!C229 -> 34732.29
A23: - | B23: CATERING | E23: =SUM(F23:I23) -> 0 | H23: =+'Distribución por línea'!C187
A24: - | B24: CERTIFICACIONES | E24: =SUM(F24:I24) -> 0 | F24: =+'Distribución por línea'!C127
A25: - | B25: COMBUSTIBLE | E25: =SUM(F25:I25) -> 6051.11 | H25: =+'Distribución por línea'!C169 -> 6051.11
A26: - | B26: COMIDA | E26: =SUM(F26:I26) -> 19390 | H26: =+'Distribución por línea'!C165 -> 19390
A27: - | B27: COMISIONES | E27: =SUM(F27:I27) -> 0
A28: - | B28: COMUNICACIONES | E28: =SUM(F28:I28) -> 5298.39 | F28: =+'Distribución por línea'!C168 -> 5298.39
A29: - | B29: CONTROL ZOOFITOSANITARIA | E29: =SUM(F29:I29) -> 0 | H29: 0
A30: - | B30: CONVENIO DE CESIÓN | E30: =SUM(F30:I30) -> 0 | H30: =+'Distribución por línea'!C159
A31: - | B31: DONACIONES | E31: =SUM(F31:I31) -> 0 | F31: =+'Distribución por línea'!C139
A32: - | B32: DERECHOS DE EXPLORACION | E32: =SUM(F32:I32) -> 0 | H32: =+'Distribución por línea'!C195
A33: - | B33: EXPENSAS | E33: =SUM(F33:I33) -> 0 | F33: =+'Distribución por línea'!C204
A34: - | B34: FERRETERÍA | E34: =SUM(F34:I34) -> 346.02 | F34: =+'Distribución por línea'!C188 -> 346.02
A35: - | B35: GASTOS BANCARIOS | E35: =SUM(F35:I35) -> 6613.93 | F35: =+'Distribución por línea'!C146 -> 6613.93
A36: - | B36: GASTOS VARIOS | E36: =SUM(F36:I36) -> 7585.25 | F36: =+'Distribución por línea'!C131+'Distribución por línea'!C124+'Distribución por línea'!C200 -> 7585.25
A37: - | B37: GASTOS VEHÍCULOS | E37: =SUM(F37:I37) -> 10991.7 | F37: =+'Distribución por línea'!C203 -> 10991.7
A38: - | B38: GASTOS CAMPAMENTO | E38: =SUM(F38:I38) -> 0 | H38: =+'Distribución por línea'!C196
A39: - | B39: GASTOS EN CONSTRUCCIÓN | E39: =SUM(F39:I39) -> 6055.09 | H39: =+'Distribución por línea'!C198 -> 6055.09
A40: - | B40: GASTOS DE COMPUTACIÓN | E40: =SUM(F40:I40) -> 3543.26 | H40: =+'Distribución por línea'!C132 -> 3543.26
A41: - | B41: GASTOS MÉDICOS | E41: =SUM(F41:I41) -> 0 | H41: =+'Distribución por línea'!C138
A42: - | B42: GASTOS CAPACITACIÓN | E42: =SUM(F42:I42) -> 0 | H42: =+'Distribución por línea'!C173
A43: - | B43: GASTOS TOPOGRÁFICOS | E43: =SUM(F43:I43) -> 13.29 | H43: =+'Distribución por línea'!C161 -> 13.29
...

Sheet Distribución por línea
A1: TxtCapitulo | B1: Texto72 | C1: txtsaldop
A2: ACTIVO
B3: 111010001 - Caja | C3: =IFERROR(VLOOKUP(B3,'Balance de sumas y saldos'!A:D,4,FALSE),) | D3: 2677221.3 | F3: =+E3-D3 -> -2677221.3
B4: 111020003 - Banco de Crédito - BCP | C4: =IFERROR(VLOOKUP(B4,'Balance de sumas y saldos'!A:D,4,FALSE),) -> 5746.23
B5: 111020001 - ICBC S.A. c/c | C5: =IFERROR(VLOOKUP(B5,'Balance de sumas y saldos'!A:D,4,FALSE),) -> 7239.24
B6: 111020005 - Banco Macro Pesos | C6: =IFERROR(VLOOKUP(B6,'Balance de sumas y saldos'!A:D,4,FALSE),) -> -15.71
B7: 111020007 - Banco Macro USD | C7: =IFERROR(VLOOKUP(B7,'Balance de sumas y saldos'!A:D,4,FALSE),) -> 981.5
B8: =+'Balance de sumas y saldos'!A11 -> 111020002 - Banco Macro Cta. Especial en pesos | C8: =IFERROR(VLOOKUP(B8,'Balance de sumas y saldos'!A:D,4,FALSE),)
B9: 111020006 - Banco Galicia c/c | C9: =IFERROR(VLOOKUP(B9,'Balance de sumas y saldos'!A:D,4,FALSE),) -> 2.67
B10: 115010001 - Fondo fima premiun | C10: =IFERROR(VLOOKUP(B10,'Balance de sumas y saldos'!A:D,4,FALSE),)
B11: 11104000 - Tarjetas Coorporativas | C11: =IFERROR(VLOOKUP(B11,'Balance de sumas y saldos'!A:D,4,FALSE),)
B12: 11401001 - Iva crédito fiscal | C12: =IFERROR(VLOOKUP(B12,'Balance de sumas y saldos'!A:D,4,FALSE),)
B13: 114010002 - IVA saldo a favor | C13: =IFERROR(VLOOKUP(B13,'Balance de sumas y saldos'!A:D,4,FALSE),) -> 1132355.3
B14: 11401003 - Retenciones y percepciones iva | C14: =IFERROR(VLOOKUP(B14,'Balance de sumas y saldos'!A:D,4,FALSE),) -> -1.7763568e-15
B15: 11401004 - Retenciones y Percepciones II.BB. | C15: =IFERROR(VLOOKUP(B15,'Balance de sumas y saldos'!A:D,4,FALSE),) -> -8.8817842e-16
B16: 11401005 - Ingresos Brutos saldo a favor | C16: =IFERROR(VLOOKUP(B16,'Balance de sumas y saldos'!A:D,4,FALSE),) -> 5340.7
B17: 11401006 - Crédito Imp. L.25413 | C17: =IFERROR(VLOOKUP(B17,'Balance de sumas y saldos'!A:D,4,FALSE),) -> 35314.56
B18: 11401010 - Imp. Gcia Mínima Presunta | C18: =IFERROR(VLOOKUP(B18,'Balance de sumas y saldos'!A:D,4,FALSE),) -> 358.96
B19: 11401012 - Ret/Perc Ganancias | C19: =IFERROR(VLOOKUP(B19,'Balance de sumas y saldos'!A:D,4,FALSE),)
B20: 11401013 - Saldo a Favor Gcia Minima Presunta | C20: =IFERROR(VLOOKUP(B20,'Balance de sumas y saldos'!A:D,4,FALSE),) -> 165.44
... B39: 12301000 - Titulos Públicos | C39: =IFERROR(VLOOKUP(B39,'Balance de sumas y saldos'!A:D,4,FALSE),)
B40: 12402000 - Muebles y Utiles | C40: =IFERROR(VLOOKUP(B40,'Balance de sumas y saldos'!A:D,4,FALSE),) -> 130976.14 | E40: =SUM(C40:C55) -> 72868.68 | F40: =+'Anexo I'!K24 -> 72868.68
B41: 12403000 - Equipos | C41: =IFERROR(VLOOKUP(B41,'Balance de sumas y saldos'!A:D,4,FALSE),) -> 58450.05 | F41: =+F40-E40 -> -1.1641532e-10
B42: 12404000 - Herramientas | C42: =IFERROR(VLOOKUP(B42,'Balance de sumas y saldos'!A:D,4,FALSE),) -> 33289.65
B43: 12405000 - Equipos de Computación | C43: =IFERROR(VLOOKUP(B43,'Balance de sumas y saldos'!A:D,4,FALSE),) -> 78372.31
B44: 12406000 - Software | C44: =IFERROR(VLOOKUP(B44,'Balance de sumas y saldos'!A:D,4,FALSE),) -> 133453.72
B45: 12407000 - Am. Ac. Muebles y Útiles | C45: =IFERROR(VLOOKUP(B45,'Balance de sumas y saldos'!A:D,4,FALSE),) -> -110762.6 | D45: 110182.16 | E45: =+C45+D45 -> -580.44
B46: 12408000 - Am. Ac. Equipos | C46: =IFERROR(VLOOKUP(B46,'Balance de sumas y saldos'!A:D,4,FALSE),) -> -55642.59 | D46: 55524.69 | E46: =+C46+D46 -> -117.9
B47: 12409000 - Am. Ac. Herramientas | C47: =IFERROR(VLOOKUP(B47,'Balance de sumas y saldos'!A:D,4,FALSE),) -> -23489.12 | D47: 23232.84 | E47: =+C47+D47 -> -256.28
B48: 12411000 - Rodados | C48: =IFERROR(VLOOKUP(B48,'Balance de sumas y saldos'!A:D,4,FALSE),) -> 279626.68
B49: 12412000 - Am. Ac. Eq. de Computación | C49: =IFERROR(VLOOKUP(B49,'Balance de sumas y saldos'!A:D,4,FALSE),) -> -67464.69 | D49: 66359.77 | E49: =+C49+D49 -> -1104.92
B50: 12413000 - Am. Ac. Software | C50: =IFERROR(VLOOKUP(B50,'Balance de sumas y saldos'!A:D,4,FALSE),) -> -133453.72 | D50: 133453.72 | E50: =+C50+D50 -> 0
B51: 12414000 - Am. Ac. Rodados | C51: =IFERROR(VLOOKUP(B51,'Balance de sumas y saldos'!A:D,4,FALSE),) -> -266119.74 | D51: 262141.62 | E51: =+C51+D51 -> -3978.12
B52: 12415000 - Equipamiento Exploración | C52: =IFERROR(VLOOKUP(B52,'Balance de sumas y saldos'!A:D,4,FALSE),) -> 136820.25
B53: 12416000 - Am. Ac. Equipamiento Exploración | C53: =IFERROR(VLOOKUP(B53,'Balance de sumas y saldos'!A:D,4,FALSE),) -> -127115.9 | D53: 125515.34 | E53: =+C53+D53 -> -1600.56
B54: 12417000 - Instalaciones | C54: =IFERROR(VLOOKUP(B54,'Balance de sumas y saldos'!A:D,4,FALSE),) -> 11629.81
B55: 12418000 - Am. Ac. Instalaciones | C55: =IFERROR(VLOOKUP(B55,'Balance de sumas y saldos'!A:D,4,FALSE),) -> -5701.57 | D55: 5524.4 | E55: =+C55+D55 -> -177.17
B56: 125010001 - Cargos Diferidos Los Menucos | C56: =IFERROR(VLOOKUP(B56,'Balance de sumas y saldos'!A:D,4,FALSE),) -> 165358.57 | F56: ACTIVO
B57: 125010002 - Cargos Diferidos Cañadón del Moro | C57: =IFERROR(VLOOKUP(B57,'Balance de sumas y saldos'!A:D,4,FALSE),) -> 1063586.4 | F57: =SUM(C3:C57) -> 3908276.5
A58: PASIVO
...

Sheet Balance de sumas y saldos
A1: SOUTHERN COPPER ARGENTINA S.R.L.
A2: BALANCE DE COMPROBACION - DOLARES
A3: 45016
A4: 1 | B4: 2 | C4: 3 | D4: 4
A5: Cuenta Contable | B5: Subcuenta | C5: Movimiento del Mes Dolares
A6: ACTIVO
A7: 111010001 - Caja | D7: 1014.2
A8: 111020003 - Banco de Crédito - BCP | D8: 5728.23
A9: 111020001 - ICBC S.A. c/c | D9: 8064.94
A10: 111020007 - Banco Macro USD | D10: 83641
A11: 111020002 - Banco Macro Cta. Especial en pesos | D11: 0
A12: 111020005 - Banco Macro Pesos | D12: 10395.91
A13: 111020006 - Banco Galicia c/c | D13: 4.84
A14: 11401001 - Iva crédito fiscal | D14: -4.5474735e-15
A15: 114010002 - IVA saldo a favor | D15: 1131450.4
A16: 11401003 - Retenciones y percepciones iva | D16: 3.5527137e-17
A17: 11401004 - Retenciones y Percepciones II.BB. | D17: 0.78
A18: 11401005 - Ingresos Brutos saldo a favor | D18: 5340.61
... A58: 125010002 - Cargos Diferidos Cañadón del Moro | D58: 1063586.4
D59: 0
D60: 0
D61: 0
D62: 0
D63: 0
D64: 0
D65: 0
D66: 0
A67: PASIVO | D67: 0
A68: 21101000 - Proveedores | D68: -37407.588
A69: 21301000 - Sueldos a pagar | D69: -1.1641532e-12
A70: 212010003 - Provisión Vacaciones | D70: -25781.52
A71: 211050000 - Previsión AID | D71: -1208275.2
A72: 211060000 - Previsión IGMP | D72: -519.11
A73: 21406000 - Sicore a pagar | D73: -136085.37
A74: 21407000 - Sicoss a pagar | D74: -11041.19
A75: 211030000 - Provision de Gastos | D75: -0.9
A76: 213010007 - Tasa Seguridad e Higiene a pagar | D76: -13.27
A77: 213010008 - Iva importación de servicios a pagar | D77: 0
A78: 213010010 - Patentes a pagar | D78: 0
A79: 212020002 - Retenciones SUSS a pagar | D79: -30.97
...
